Workbook
Name Период_1: #REF!
Name Период_10: #REF!
Name Период_11: #REF!
Name Период_12: #REF!
Name Период_13: #REF!
Name Период_14: #REF!
Name Период_15: #REF!
Name Период_16: #REF!
Name Период_17: #REF!
Name Период_18: #REF!
Name Период_19: #REF!
Name Период_2: #REF!
Name Период_20: #REF!
Name Период_21: #REF!
Name Период_22: #REF!
Name Период_23: #REF!
Name Период_24: #REF!
Name Период_25: #REF!
Name Период_26: #REF!
Name Период_3: #REF!
Name Период_4: #REF!
Name Период_5: #REF!
Name Период_6: #REF!
Name Период_7: #REF!
Name Период_8: #REF!
Name Период_9: #REF!
Name СП_R100C10: #REF!
Name СП_R100C11: #REF!
Name СП_R100C12: #REF!
Name СП_R100C13: #REF!
Name СП_R100C14: #REF!
Name СП_R100C15: #REF!
Name СП_R100C16: #REF!
Name СП_R100C17: #REF!
Name СП_R100C18: #REF!
Name СП_R100C19: #REF!
Name СП_R100C20: #REF!
Name СП_R100C21: #REF!
Name СП_R100C22: #REF!
Name СП_R100C23: #REF!
Name СП_R100C24: #REF!
Name СП_R100C25: #REF!
Name СП_R100C26: #REF!
Name СП_R100C27: #REF!
Name СП_R100C28: #REF!
Name СП_R100C3: #REF!
Name СП_R100C4: #REF!
Name СП_R100C5: #REF!
Name СП_R100C6: #REF!
Name СП_R100C7: #REF!
Name СП_R100C8: #REF!
Name СП_R100C9: #REF!
Name СП_R101C10: #REF!
Name СП_R101C11: #REF!
Name СП_R101C12: #REF!
Name СП_R101C13: #REF!
Name СП_R101C14: #REF!
Name СП_R101C15: #REF!
Name СП_R101C16: #REF!
Name СП_R101C17: #REF!

Sheet МАСТЕР ПЛАН
AA2: Вариант 4 | AE2: FALSE
AA4: 1+2 оч | AB4: 1оч | AC4: 2оч
Z5: жилье | AA5: =AB5+AC5 -> 169659.3 | AB5: 113733.8 | AC5: 55925.5
Z6: нежилье | AA6: =AB6+AC6 -> 8263.1 | AB6: 5160.1 | AC6: 3103
AA7: =AA5+AA6 -> 177922.4 | AB7: =AB5+AB6 -> 118893.9 | AC7: =AC5+AC6 -> 59028.5
Z8: ЗУ | AA8: =AB8+AC8 -> 47620 | AB8: =AC17 -> 29890 | AC8: =AB17 -> 17730
AA11: Вариант 3 | AE11: FALSE
AA13: 1+2 оч | AB13: 1оч | AC13: 2оч
Z14: жилье | AA14: =AB14+AC14 -> 169659.3 | AB14: 55925.5 | AC14: 113733.8
Z15: нежилье | AA15: =AB15+AC15 -> 8263.1 | AB15: 3103 | AC15: 5160.1
AA16: =AA14+AA15 -> 177922.4 | AB16: =AB14+AB15 -> 59028.5 | AC16: =AC14+AC15 -> 118893.9
Z17: ЗУ | AA17: =AB17+AC17 -> 47620 | AB17: 17730 | AC17: =29890 -> 29890
AA19: Вариант 1 | AE19: TRUE
AB20: =AB22/$AA$22 -> 0.53874801 | AC20: =AC22/$AA$22 -> 0.46125199
AA21: 1+2 оч | AB21: 1оч | AC21: 2оч
Z22: жилье | AA22: =AB22+AC22 -> 169435.8 | AB22: 91283.2 | AC22: 78152.6
Z23: нежилье | AA23: =AB23+AC23 -> 8707.4 | AB23: 5042.8 | AC23: 3664.6
AA24: =AA22+AA23 -> 178143.2 | AB24: =AB22+AB23 -> 96326 | AC24: =AC22+AC23 -> 81817.2
Z25: ЗУ | AA25: =AB25+AC25 -> 47620 | AB25: 25440 | AC25: 22180
AA28: Вариант 2 | AE28: FALSE
AB29: =DB!B107 -> 0.5 | AC29: =1-AB29 -> 0.5
AA30: 1+2 оч | AB30: 1оч | AC30: 2оч
Z31: жилье | AA31: 169659.3 | AB31: =$AA$31*AB29 -> 84829.65 | AC31: =$AA$31*AC29 -> 84829.65
Z32: нежилье | AA32: 8263.1 | AB32: =$AA$32*AB29 -> 4131.55 | AC32: =$AA$32*AC29 -> 4131.55
AA33: 177922.4 | AB33: =AB31+AB32 -> 88961.2 | AC33: =AC31+AC32 -> 88961.2
Z34: ЗУ | AA34: =AB34+AC34 -> 47620 | AB34: =29890 -> 29890 | AC34: 17730
AA41: ПРИБЫЛЬ | AB41: =DB!U38 -> 9345.5509 | AC41: 9215.744 | AD41: =AB41-AC41 -> 129.80687
AA42: PV | AB42: =DB!U44 -> 1866.4393 | AC42: 1883.7835 | AD42: =AB42-AC42 -> -17.344287
AA43: LLSR | AB43: =DB!U43 -> 1.1966655 | AC43: 1.1946846 | AD43: =AB43-AC43 -> 0.0019809278
AA44: IRR ПРОЕКТА (pre-tax) | AB44: =DB!U41 -> 0.1755044 | AC44: 0.17660578 | AD44: =AB44-AC44 -> -0.0011013809
G55: Вопросы:
F57: 1 | G57: СОШ - сроки
F58: 2 | G58: м/м - кол-во в подземной части? Площадь подземки на 1 м/м
F59: 3 | G59: средняя площадь квартиры

Sheet RESUME
B2: Резюме изменений проекта (вкладка RESUME)
B3: Название проекта: | E3: =DB!C2 -> КАСАТКИНА | J3: =OFFSET($Q3,,MATCH(J$5,$R$5:$W$5,0)) -> 📌 | K3: =OFFSET($Q3,,MATCH(K$5,$R$5:$W$5,0)) -> 📌 | L3: =OFFSET($Q3,,MATCH(L$5,$R$5:$W$5,0)) -> 📌 | R3: 📌 | S3: 📌 | T3: 📌 | U3: 📌 | V3: 📌 | W3: 📌
H4: =K4 -> 1 оч | I4: =L4 -> 2 оч | J4: =OFFSET($Q4,,MATCH(J$5,$R$5:$W$5,0)) -> ТЭПы 50 / 50 | K4: =OFFSET($Q4,,MATCH(K$5,$R$5:$W$5,0)) -> 1 оч | L4: =OFFSET($Q4,,MATCH(L$5,$R$5:$W$5,0)) -> 2 оч | M4: =CONCATENATE(K4," vs ",L4) -> 1 оч vs 2 оч | N4: Текущая ФМ <2Q2025 | R4: ТЭПы 50 / 50 | S4: 1 оч | T4: 2 оч | V4: 1 оч | W4: 2 оч
B5: ПОКАЗАТЕЛИ | F5: млн.руб. | H5: =K5 -> 45779 | I5: =L5 -> 45780 | J5: 45778 | K5: 45779 | L5: 45780 | M5: +/- | N5: FACT | O5: PLAN | P5: Комм. | R5: 45778 | S5: =R5+1 -> 45779 | T5: =R5+2 -> 45780 | U5: 45809 | V5: 45810 | W5: 45811
B6: ПЛОЩАДЬ ЗУ | H6: кв.м. | J6: =SUMIFS($R6:$W6,$R$5:$W$5,$J$5) -> 47620 | K6: =SUMIFS($R6:$W6,$R$5:$W$5,$K$5) -> 25440 | L6: =SUMIFS($R6:$W6,$R$5:$W$5,$L$5) -> 22180 | M6: =L6-K6 -> -3260 | P6: =LEFT(Y6,4) | R6: =DB!P51 -> 47620 | S6: ='DB1'!P51 -> 25440 | T6: ='DB2'!P51 -> 22180
B7: ПЛОТНОСТЬ | F7: 40000 | G7: (м2/Га) | H7: кв.м. | J7: =SUMIFS($R7:$W7,$R$5:$W$5,$J$5) -> 35000 | K7: =SUMIFS($R7:$W7,$R$5:$W$5,$K$5) -> 35000 | L7: =SUMIFS($R7:$W7,$R$5:$W$5,$L$5) -> 35000 | M7: =L7-K7 -> 0 | P7: =LEFT(Y7,4) | R7: =DB!P2 -> 35000 | S7: ='DB1'!P2 -> 35000 | T7: ='DB2'!P2 -> 35000
B8: ГНС бум. | H8: кв.м. | J8: =SUMIFS($R8:$W8,$R$5:$W$5,$J$5) -> 178143.2 | K8: =SUMIFS($R8:$W8,$R$5:$W$5,$K$5) -> 96326 | L8: =SUMIFS($R8:$W8,$R$5:$W$5,$L$5) -> 81817.2 | M8: =L8-K8 -> -14508.8 | P8: =LEFT(Y8,4) | R8: =DB!F7 -> 178143.2 | S8: ='DB1'!F7 -> 96326 | T8: ='DB2'!F7 -> 81817.2
B9: ГНС | H9: кв.м. | J9: =SUMIFS($R9:$W9,$R$5:$W$5,$J$5) -> 178143.2 | K9: =SUMIFS($R9:$W9,$R$5:$W$5,$K$5) -> 96326 | L9: =SUMIFS($R9:$W9,$R$5:$W$5,$L$5) -> 81817.2 | M9: =L9-K9 -> -14508.8 | P9: =LEFT(Y9,4) | R9: =DB!F7 -> 178143.2 | S9: ='DB1'!F7 -> 96326 | T9: ='DB2'!F7 -> 81817.2
B10: =DB!D8 -> 0.95112135 | C10: квартиры | H10: кв.м. | J10: =SUMIFS($R10:$W10,$R$5:$W$5,$J$5) -> 169435.8 | K10: =SUMIFS($R10:$W10,$R$5:$W$5,$K$5) -> 91283.2 | L10: =SUMIFS($R10:$W10,$R$5:$W$5,$L$5) -> 78152.6 | M10: =L10-K10 -> -13130.6 | P10: =LEFT(Y10,4) | R10: =DB!F8 -> 169435.8 | S10: ='DB1'!F8 -> 91283.2 | T10: ='DB2'!F8 -> 78152.6
C11: офисы | H11: кв.м. | J11: =SUMIFS($R11:$W11,$R$5:$W$5,$J$5) -> 0 | K11: =SUMIFS($R11:$W11,$R$5:$W$5,$K$5) -> 0 | L11: =SUMIFS($R11:$W11,$R$5:$W$5,$L$5) -> 0 | M11: =L11-K11 -> 0 | P11: =LEFT(Y11,4)
B12: ='DB1'!D11 -> 0.05235139 | C12: стритритейл | H12: кв.м. | J12: =SUMIFS($R12:$W12,$R$5:$W$5,$J$5) -> 8707.4 | K12: =SUMIFS($R12:$W12,$R$5:$W$5,$K$5) -> 5042.8 | L12: =SUMIFS($R12:$W12,$R$5:$W$5,$L$5) -> 3664.6 | M12: =L12-K12 -> -1378.2 | P12: =LEFT(Y12,4) | R12: =DB!F11 -> 8707.4 | S12: ='DB1'!F11 -> 5042.8 | T12: ='DB2'!F11 -> 3664.6
C13: ДОУ | H13: кв.м. | J13: =SUMIFS($R13:$W13,$R$5:$W$5,$J$5) -> 0 | K13: =SUMIFS($R13:$W13,$R$5:$W$5,$K$5) -> 0 | L13: =SUMIFS($R13:$W13,$R$5:$W$5,$L$5) -> 0 | M13: =L13-K13 -> 0 | P13: =LEFT(Y13,4)
B14: ОБЩАЯ ПЛОЩАДЬ ОБЪЕКТА по стандарту СП (РНС и экспертиза) | H14: кв.м. | J14: =SUMIFS($R14:$W14,$R$5:$W$5,$J$5) -> 0 | K14: =SUMIFS($R14:$W14,$R$5:$W$5,$K$5) -> 0 | L14: =SUMIFS($R14:$W14,$R$5:$W$5,$L$5) -> 0 | M14: =L14-K14 -> 0 | P14: =LEFT(Y14,4) | R14: =R15+R16 -> 0 | S14: =S15+S16 -> 0 | T14: =T15+T16 -> 0
B15: наземная часть | F15: 0.0535 | G15: (стены) | H15: кв.м. | J15: =SUMIFS($R15:$W15,$R$5:$W$5,$J$5) -> 0 | K15: =SUMIFS($R15:$W15,$R$5:$W$5,$K$5) -> 0 | L15: =SUMIFS($R15:$W15,$R$5:$W$5,$L$5) -> 0 | M15: =L15-K15 -> 0 | P15: =LEFT(Y15,4)
B16: подземная часть | H16: кв.м. | J16: =SUMIFS($R16:$W16,$R$5:$W$5,$J$5) -> 0 | K16: =SUMIFS($R16:$W16,$R$5:$W$5,$K$5) -> 0 | L16: =SUMIFS($R16:$W16,$R$5:$W$5,$L$5) -> 0 | M16: =L16-K16 -> 0 | P16: =LEFT(Y16,4)
B17: ОБЩАЯ ПЛОЩАДЬ ОБЪЕКТА по станд. МРГ | F17: =DB!G5 -> 0.07 | G17: (стены) | H17: кв.м. | J17: =SUMIFS($R17:$W17,$R$5:$W$5,$J$5) -> 210153.18 | K17: =SUMIFS($R17:$W17,$R$5:$W$5,$K$5) -> 113543.18 | L17: =SUMIFS($R17:$W17,$R$5:$W$5,$L$5) -> 96609.996 | M17: =L17-K17 -> -16933.184 | P17: =LEFT(Y17,4) | R17: =R18+R23 -> 210153.18 | S17: =S18+S23 -> 113543.18 | T17: =T18+T23 -> 96609.996
B18: наземная часть | H18: кв.м. | J18: =SUMIFS($R18:$W18,$R$5:$W$5,$J$5) -> 165673.18 | K18: =SUMIFS($R18:$W18,$R$5:$W$5,$K$5) -> 89583.18 | L18: =SUMIFS($R18:$W18,$R$5:$W$5,$L$5) -> 76089.996 | M18: =L18-K18 -> -13493.184 | P18: =LEFT(Y18,4) | R18: =SUM(R19:R22) -> 165673.18 | S18: =SUM(S19:S22) -> 89583.18 | T18: =SUM(T19:T22) -> 76089.996
C19: квартиры | H19: кв.м. | J19: =SUMIFS($R19:$W19,$R$5:$W$5,$J$5) -> 157575.29 | K19: =SUMIFS($R19:$W19,$R$5:$W$5,$K$5) -> 84893.376 | L19: =SUMIFS($R19:$W19,$R$5:$W$5,$L$5) -> 72681.918 | M19: =L19-K19 -> -12211.458 | P19: =LEFT(Y19,4) | R19: =DB!G8 -> 157575.29 | S19: ='DB1'!G8 -> 84893.376 | T19: ='DB2'!G8 -> 72681.918
C20: офисы | H20: кв.м. | J20: =SUMIFS($R20:$W20,$R$5:$W$5,$J$5) -> 0 | K20: =SUMIFS($R20:$W20,$R$5:$W$5,$K$5) -> 0 | L20: =SUMIFS($R20:$W20,$R$5:$W$5,$L$5) -> 0 | M20: =L20-K20 -> 0 | P20: =LEFT(Y20,4)
C21: стритритейл | H21: кв.м. | J21: =SUMIFS($R21:$W21,$R$5:$W$5,$J$5) -> 8097.882 | K21: =SUMIFS($R21:$W21,$R$5:$W$5,$K$5) -> 4689.804 | L21: =SUMIFS($R21:$W21,$R$5:$W$5,$L$5) -> 3408.078 | M21: =L21-K21 -> -1281.726 | P21: =LEFT(Y21,4) | R21: =DB!G11 -> 8097.882 | S21: ='DB1'!G11 -> 4689.804 | T21: ='DB2'!G11 -> 3408.078
C22: ДОУ | H22: кв.м. | J22: =SUMIFS($R22:$W22,$R$5:$W$5,$J$5) -> 0 | K22: =SUMIFS($R22:$W22,$R$5:$W$5,$K$5) -> 0 | L22: =SUMIFS($R22:$W22,$R$5:$W$5,$L$5) -> 0 | M22: =L22-K22 -> 0 | P22: =LEFT(Y22,4)
B23: подземная часть | H23: кв.м. | J23: =SUMIFS($R23:$W23,$R$5:$W$5,$J$5) -> 44480 | K23: =SUMIFS($R23:$W23,$R$5:$W$5,$K$5) -> 23960 | L23: =SUMIFS($R23:$W23,$R$5:$W$5,$L$5) -> 20520 | M23: =L23-K23 -> -3440 | P23: =LEFT(Y23,4) | R23: =SUM(R24:R25) -> 44480 | S23: =SUM(S24:S25) -> 23960 | T23: =SUM(T24:T25) -> 20520
C24: парковка | F24: =DB!D16 -> 40 | G24: м2/м-м | H24: кв.м. | J24: =SUMIFS($R24:$W24,$R$5:$W$5,$J$5) -> 44480 | K24: =SUMIFS($R24:$W24,$R$5:$W$5,$K$5) -> 23960 | L24: =SUMIFS($R24:$W24,$R$5:$W$5,$L$5) -> 20520 | M24: =L24-K24 -> -3440 | P24: =LEFT(Y24,4) | R24: =DB!G16 -> 44480 | S24: ='DB1'!G16 -> 23960 | T24: ='DB2'!G16 -> 20520
C25: кладовки | H25: кв.м. | J25: =SUMIFS($R25:$W25,$R$5:$W$5,$J$5) -> 0 | K25: =SUMIFS($R25:$W25,$R$5:$W$5,$K$5) -> 0 | L25: =SUMIFS($R25:$W25,$R$5:$W$5,$L$5) -> 0 | M25: =L25-K25 -> 0 | P25: =LEFT(Y25,4)
B26: ПОЛЕЗНАЯ ПЛОЩАДЬ ОБЪЕКТА | H26: кв.м. | J26: =SUMIFS($R26:$W26,$R$5:$W$5,$J$5) -> 116376.12 | K26: =SUMIFS($R26:$W26,$R$5:$W$5,$K$5) -> 62942.716 | L26: =SUMIFS($R26:$W26,$R$5:$W$5,$L$5) -> 53433.401 | M26: =L26-K26 -> -9509.3151 | P26: =LEFT(Y26,4) | R26: =SUM(R27,R35) -> 116376.12 | S26: =SUM(S27,S35) -> 62942.716 | T26: =SUM(T27,T35) -> 53433.401
B27: наземная часть | H27: кв.м. | J27: =SUMIFS($R27:$W27,$R$5:$W$5,$J$5) -> 116376.12 | K27: =SUMIFS($R27:$W27,$R$5:$W$5,$K$5) -> 62942.716 | L27: =SUMIFS($R27:$W27,$R$5:$W$5,$L$5) -> 53433.401 | M27: =L27-K27 -> -9509.3151 | P27: =LEFT(Y27,4) | R27: =SUM(R28,R32,R33,R34) -> 116376.12 | S27: =SUM(S28,S32,S33,S34) -> 62942.716 | T27: =SUM(T28,T32,T33,T34) -> 53433.401
C28: квартиры | H28: кв.м. | J28: =SUMIFS($R28:$W28,$R$5:$W$5,$J$5) -> 110302.71 | K28: =SUMIFS($R28:$W28,$R$5:$W$5,$K$5) -> 59425.363 | L28: =SUMIFS($R28:$W28,$R$5:$W$5,$L$5) -> 50877.343 | M28: =L28-K28 -> -8548.0206 | P28: =LEFT(Y28,4) | R28: =SUM(R29:R31) -> 110302.71 | S28: =SUM(S29:S31) -> 59425.363 | T28: =SUM(T29:T31) -> 50877.343
D29: MR Base | H29: кв.м. | J29: =SUMIFS($R29:$W29,$R$5:$W$5,$J$5) -> 110302.71 | K29: =SUMIFS($R29:$W29,$R$5:$W$5,$K$5) -> 59425.363 | L29: =SUMIFS($R29:$W29,$R$5:$W$5,$L$5) -> 50877.343 | M29: =L29-K29 -> -8548.0206 | P29: =LEFT(Y29,4) | R29: =DB!H8 -> 110302.71 | S29: ='DB1'!H8 -> 59425.363 | T29: ='DB2'!H8 -> 50877.343
D30: MR Ready | H30: кв.м. | J30: =SUMIFS($R30:$W30,$R$5:$W$5,$J$5) -> 0 | K30: =SUMIFS($R30:$W30,$R$5:$W$5,$K$5) -> 0 | L30: =SUMIFS($R30:$W30,$R$5:$W$5,$L$5) -> 0 | M30: =L30-K30 -> 0 | P30: =LEFT(Y30,4)
D31: без отделки | H31: кв.м. | J31: =SUMIFS($R31:$W31,$R$5:$W$5,$J$5) -> 0 | K31: =SUMIFS($R31:$W31,$R$5:$W$5,$K$5) -> 0 | L31: =SUMIFS($R31:$W31,$R$5:$W$5,$L$5) -> 0 | M31: =L31-K31 -> 0 | P31: =LEFT(Y31,4)
C32: офисы | H32: кв.м. | J32: =SUMIFS($R32:$W32,$R$5:$W$5,$J$5) -> 0 | K32: =SUMIFS($R32:$W32,$R$5:$W$5,$K$5) -> 0 | L32: =SUMIFS($R32:$W32,$R$5:$W$5,$L$5) -> 0 | M32: =L32-K32 -> 0 | P32: =LEFT(Y32,4)
C33: стритритейл | H33: кв.м. | J33: =SUMIFS($R33:$W33,$R$5:$W$5,$J$5) -> 6073.4115 | K33: =SUMIFS($R33:$W33,$R$5:$W$5,$K$5) -> 3517.353 | L33: =SUMIFS($R33:$W33,$R$5:$W$5,$L$5) -> 2556.0585 | M33: =L33-K33 -> -961.2945 | P33: =LEFT(Y33,4) | R33: =DB!H11 -> 6073.4115 | S33: ='DB1'!H11 -> 3517.353 | T33: ='DB2'!H11 -> 2556.0585
C34: ДОУ | H34: кв.м. | J34: =SUMIFS($R34:$W34,$R$5:$W$5,$J$5) -> 0 | K34: =SUMIFS($R34:$W34,$R$5:$W$5,$K$5) -> 0 | L34: =SUMIFS($R34:$W34,$R$5:$W$5,$L$5) -> 0 | M34: =L34-K34 -> 0 | P34: =LEFT(Y34,4)
B35: подземная часть | H35: кв.м. | J35: =SUMIFS($R35:$W35,$R$5:$W$5,$J$5) -> 0 | K35: =SUMIFS($R35:$W35,$R$5:$W$5,$K$5) -> 0 | L35: =SUMIFS($R35:$W35,$R$5:$W$5,$L$5) -> 0 | M35: =L35-K35 -> 0 | P35: =LEFT(Y35,4) | R35: =SUM(R36) -> 0 | S35: =SUM(S36) -> 0 | T35: =SUM(T36) -> 0
C36: кладовки | H36: кв.м. | J36: =SUMIFS($R36:$W36,$R$5:$W$5,$J$5) -> 0 | K36: =SUMIFS($R36:$W36,$R$5:$W$5,$K$5) -> 0 | L36: =SUMIFS($R36:$W36,$R$5:$W$5,$L$5) -> 0 | M36: =L36-K36 -> 0 | P36: =LEFT(Y36,4)
B37: LOSS-FACTOR по стандарту МР Групп | H37: % | J37: =SUMIFS($R37:$W37,$R$5:$W$5,$J$5) -> 0.29755607 | K37: =SUMIFS($R37:$W37,$R$5:$W$5,$K$5) -> 0.29738243 | L37: =SUMIFS($R37:$W37,$R$5:$W$5,$L$5) -> 0.2977605 | M37: =L37-K37 -> 0.00037806485 | P37: =LEFT(Y37,4) | R37: =DB!I18 -> 0.29755607 | S37: ='DB1'!I18 -> 0.29738243 | T37: ='DB2'!I18 -> 0.2977605
B38: квартиры | H38: % | J38: =SUMIFS($R38:$W38,$R$5:$W$5,$J$5) -> 0.3 | K38: =SUMIFS($R38:$W38,$R$5:$W$5,$K$5) -> 0.3 | L38: =SUMIFS($R38:$W38,$R$5:$W$5,$L$5) -> 0.3 | M38: =L38-K38 -> 0 | P38: =LEFT(Y38,4) | R38: =DB!I8 -> 0.3 | S38: ='DB1'!I8 -> 0.3 | T38: ='DB2'!I8 -> 0.3
B39: офисы | H39: % | J39: =SUMIFS($R39:$W39,$R$5:$W$5,$J$5) -> 0 | K39: =SUMIFS($R39:$W39,$R$5:$W$5,$K$5) -> 0 | L39: =SUMIFS($R39:$W39,$R$5:$W$5,$L$5) -> 0 | M39: =L39-K39 -> 0 | P39: =LEFT(Y39,4)
B40: стритритейл | H40: % | J40: =SUMIFS($R40:$W40,$R$5:$W$5,$J$5) -> 0.25 | K40: =SUMIFS($R40:$W40,$R$5:$W$5,$K$5) -> 0.25 | L40: =SUMIFS($R40:$W40,$R$5:$W$5,$L$5) -> 0.25 | M40: =L40-K40 -> 0 | P40: =LEFT(Y40,4) | R40: =DB!I11 -> 0.25 | S40: ='DB1'!I11 -> 0.25 | T40: ='DB2'!I11 -> 0.25
B41: КОЛИЧЕСТВО ЭЛЕМЕНТОВ ОБЪЕКТА | H41: шт. | J41: =SUMIFS($R41:$W41,$R$5:$W$5,$J$5) -> 3254 | K41: =SUMIFS($R41:$W41,$R$5:$W$5,$K$5) -> 1755 | L41: =SUMIFS($R41:$W41,$R$5:$W$5,$L$5) -> 1499 | M41: =L41-K41 -> -256 | P41: =LEFT(Y41,4) | R41: =SUM(R42,R46) -> 3254 | S41: =SUM(S42,S46) -> 1755 | T41: =SUM(T42,T46) -> 1499
...

Sheet DB
B2: ПРОЕКТ | C2: КАСАТКИНА | E2: ОЧЕРЕДЬ | F2: 1+2 очереди | G2: ЗУ | H2: =P48 -> 77:02:0019010:102 | L2: ПЛОЩАДЬ ЗУ | M2: =P51/10000 -> 4.762 | O2: ПЛОТНОСТЬ | P2: 35000 | Q2: АДРЕС | R2: ул. КАСАТКИНА, ВЛ. 7 | U2: 45826
B5: ТЭПы | F5: стены = | G5: 0.07 | L5: ДОХОДЫ
F6: ГНС | G6: ОБЩАЯ ПЛОЩАДЬ | H6: ПОЛЕЗНАЯ ПЛОЩАДЬ | I6: LF, % | J6: КОЛ-ВО | P6: ЦЕНА → | Q6: ЦЕНА ← | R6: СРЕДНЯЯ ЦЕНА | S6: ДОХОД, млн. руб. | T6: % | U6: ОБЪЕМ ПРОДАЖ, в кв.
B7: НАЗЕМНАЯ ЧАСТЬ | E7: S лота | F7: =SUM(F8:F14) -> 178143.2 | G7: =SUM(G8:G14) -> 165673.18 | H7: =SUM(H8:H14) -> 116376.12 | I7: =IFERROR(1-SUM(H8:H12)/SUM(G8:G12),"") -> 0.29755607 | L7: =B7 -> НАЗЕМНАЯ ЧАСТЬ | M7: старт | N7: % пост. | O7: c/c | P7: =(J43+J53+P42-S16)/H7*1000 -> 511.42982
A8: ЖИЛАЯ | B8: КВАРТИРЫ | D8: =F8/$F$7 -> 0.95112135 | E8: 53 | F8: ='DB1'!F8+'DB2'!F8 -> 169435.8 | G8: ='DB1'!G8+'DB2'!G8 -> 157575.29 | H8: ='DB1'!H8+'DB2'!H8 -> 110302.71 | I8: 0.3 | J8: ='DB1'!J8+'DB2'!J8 -> 2081 | L8: =B8 -> КВАРТИРЫ | M8: =U25 -> 46296 | O8: =Q8/P8-1 -> 0.35887677 | P8: =_xlfn.MINIFS(CF!$S$24:$AP$24,CF!$S$9:$AP$9,">0") -> 522.9 | Q8: =_xlfn.MAXIFS(CF!$S$24:$AP$24,CF!$S$9:$AP$9,">0") -> 710.55666 | R8: 630 | S8: ='DB1'!S8+'DB2'!S8 -> 69490.705 | T8: =S8/$S$18 -> 0.88246543 | U8: =AVERAGE(CF!S9:AP9) -> 4595.9461
A9: ЖИЛАЯ | B9: АПАРТАМЕНТЫ | E9: =IFERROR(H9/J9,0) -> 0 | F9: ='DB1'!F9+'DB2'!F9 -> 0 | G9: ='DB1'!G9+'DB2'!G9 -> 0 | H9: ='DB1'!H9+'DB2'!H9 -> 0 | I9: 0 | J9: ='DB1'!J9+'DB2'!J9 -> 0 | L9: =B9 -> АПАРТАМЕНТЫ | R9: =IFERROR(S9/H9*1000,0) -> 0 | S9: ='DB1'!S9+'DB2'!S9 -> 0 | T9: =S9/$S$18 -> 0
A10: НЕЖИЛАЯ | B10: ОФИСЫ | E10: =IFERROR(H10/J10,0) -> 0 | F10: ='DB1'!F10+'DB2'!F10 -> 0 | G10: ='DB1'!G10+'DB2'!G10 -> 0 | H10: ='DB1'!H10+'DB2'!H10 -> 0 | I10: 0 | J10: ='DB1'!J10+'DB2'!J10 -> 0 | L10: =B10 -> ОФИСЫ | R10: =IFERROR(S10/H10*1000,0) -> 0 | S10: ='DB1'!S10+'DB2'!S10 -> 0 | T10: =S10/$S$18 -> 0
A11: ТОРГОВЛЯ | B11: РИТЕЙЛ | D11: =F11/$F$7 -> 0.048878655 | E11: =IFERROR(H11/J11,0) -> 99.564123 | F11: ='DB1'!F11+'DB2'!F11 -> 8707.4 | G11: ='DB1'!G11+'DB2'!G11 -> 8097.882 | H11: ='DB1'!H11+'DB2'!H11 -> 6073.4115 | I11: 0.25 | J11: ='DB1'!J11+'DB2'!J11 -> 61 | L11: =B11 -> РИТЕЙЛ | M11: 1 | O11: =Q11/P11-1 -> 0 | P11: =_xlfn.MINIFS(CF!$S$29:$AP$29,CF!$S$16:$AP$16,">0") -> 700 | Q11: =_xlfn.MAXIFS(CF!$S$29:$AP$29,CF!$S$16:$AP$16,">0") -> 700 | R11: =IFERROR(S11/H11*1000,0) -> 700 | S11: ='DB1'!S11+'DB2'!S11 -> 4251.388 | T11: =S11/$S$18 -> 0.053988559
A12: ТОРГОВЛЯ | B12: ТЦ | E12: =IFERROR(H12/J12,0) -> 0 | F12: ='DB1'!F12+'DB2'!F12 -> 0 | G12: ='DB1'!G12+'DB2'!G12 -> 0 | H12: ='DB1'!H12+'DB2'!H12 -> 0 | I12: 0 | J12: ='DB1'!J12+'DB2'!J12 -> 0 | L12: =B12 -> ТЦ | P12: =#REF! -> #REF! | Q12: =#REF! -> #REF! | R12: =IFERROR(S12/H12*1000,0) -> 0 | S12: ='DB1'!S12+'DB2'!S12 -> 0 | T12: =S12/$S$18 -> 0
B13: ШКОЛА | C13: мест | D13: ='DB1'!D13+'DB2'!D13 -> 1000 | F13: ='DB1'!F13+'DB2'!F13 -> 0 | G13: ='DB1'!G13+'DB2'!G13 -> 0 | H13: ='DB1'!H13+'DB2'!H13 -> 0 | I13: =IFERROR(1-(H13/G13),0) -> 0 | J13: ='DB1'!J13+'DB2'!J13 -> 0 | L13: =B13 -> ШКОЛА | R13: =IFERROR(S13/H13*1000,0) -> 0 | S13: ='DB1'!S13+'DB2'!S13 -> 0
A14: =A13 -> 0 | B14: ДОУ | C14: мест | D14: ='DB1'!D14+'DB2'!D14 -> 0 | F14: ='DB1'!F14+'DB2'!F14 -> 0 | G14: ='DB1'!G14+'DB2'!G14 -> 0 | H14: ='DB1'!H14+'DB2'!H14 -> 0 | I14: =IFERROR(1-(H14/G14),0) -> 0 | J14: ='DB1'!J14+'DB2'!J14 -> 0 | L14: =B14 -> ДОУ | R14: =IFERROR(S14/H14*1000,0) -> 0 | S14: ='DB1'!S14+'DB2'!S14 -> 0
B15: ПОДЗЕМНАЯ ЧАСТЬ | D15: S общ. | E15: S пол. | G15: =SUM(G16:G17) -> 44480 | H15: =SUM(H16:H17) -> 16680 | L15: =B15 -> ПОДЗЕМНАЯ ЧАСТЬ
B16: ПАРКИНГ ЖИЛЬЕ | C16: =J16/J8 -> 0.53435848 | D16: 40 | E16: 15 | F16: ='DB1'!F16+'DB2'!F16 -> 0 | G16: ='DB1'!G16+'DB2'!G16 -> 44480 | H16: ='DB1'!H16+'DB2'!H16 -> 16680 | J16: ='DB1'!J16+'DB2'!J16 -> 1112 | L16: =B16 -> ПАРКИНГ ЖИЛЬЕ | N16: 0.7 | P16: =_xlfn.MINIFS(CF!$S$33:$AP$33,CF!$S$18:$AP$18,">0") -> 4500 | Q16: =_xlfn.MAXIFS(CF!$S$33:$AP$33,CF!$S$18:$AP$18,">0") -> 4500 | R16: =IFERROR(S16/J16*1000,0) -> 4500 | S16: ='DB1'!S16+'DB2'!S16 -> 5004 | T16: =S16/$S$18 -> 0.06354601
B17: ПАРКИНГ ОФИС | F17: ='DB1'!F17+'DB2'!F17 -> 0 | G17: ='DB1'!G17+'DB2'!G17 -> 0 | H17: ='DB1'!H17+'DB2'!H17 -> 0 | J17: ='DB1'!J17+'DB2'!J17 -> 0 | L17: =B17 -> ПАРКИНГ ОФИС | N17: 0.7 | R17: =IFERROR(S17/J17*1000,0) -> 0 | S17: ='DB1'!S17+'DB2'!S17 -> 0 | T17: =S17/$S$18 -> 0
B18: ПЛОЩАДИ | F18: =F15+F7 -> 178143.2 | G18: =G15+G7 -> 210153.18 | H18: =SUM(H7,H15) -> 133056.12 | I18: =IFERROR(100%-SUM(H8:H12)/SUM(G8:G12),) -> 0.29755607 | L18: ДОХОДЫ | S18: =SUM(S8:S17) -> 78746.093
B20: ИНВЕСТИЦИИ | L20: ФИНАНСИРОВАНИЕ | R20: СРОКИ
H21: руб./S общ. | I21: руб./S пол. | J21: млн.руб. | L21: КРЕДИТ | U21: кв.
B22: ВХОД | F22: =J22/M2 -> 806.66648 | G22: за Га | H22: =IFERROR(J22/$G$18*1000000,0) -> 18278.79 | I22: =IFERROR(J22/$H$18*1000000,0) -> 28870.118 | J22: ='DB1'!J22+'DB2'!J22 -> 3841.3458 | L22: СТАВКИ | P22: ='TS1'!J85 -> 0.2 | R22: НАЧАЛО РАСЧЕТОВ | U22: 45017
B23: FINDERS FEE | G23: % от входа | H23: =IFERROR(J23/$G$18*1000000,0) -> 0 | I23: =IFERROR(J23/$H$18*1000000,0) -> 0 | J23: ='DB1'!J23+'DB2'!J23 -> 0 | L23: СТАВКА бридж | N23: 0.05 | P23: =P22+N23 -> 0.25 | R23: НАЧАЛО ПРОЕКТА | U23: 45748
B24: ЗЕМЕЛЬНО-ПРАВОВЫЕ ВОПРОСЫ | H24: =J24/$G$18*1000000 -> 23436.307 | I24: =IFERROR(J24/$H$18*1000000,0) -> 37016.069 | J24: ='DB1'!J24+'DB2'!J24 -> 4925.2144 | L24: СТАВКА проектное фин-ие | N24: 0.038 | P24: =P22+N24 -> 0.238 | R24: СРОК ИРД | U24: 5
B25: ВРИ | C25: =IF(D25>0,"со скидкой",0) -> 0 | H25: =IFERROR(J25/$G$18*1000000,0) -> 40248.472 | I25: =IFERROR(J25/$H$18*1000000,0) -> 63569.75 | J25: ='DB1'!J25+'DB2'!J25 -> 8458.3441 | L25: СТАВКА под эскроу | P25: =N24 -> 0.038 | R25: РНС 1 | U25: ='DB1'!U25 -> 46296
B26: ЛЬГОТА | H26: =IFERROR(J26/$G$18*1000000,0) -> -40248.472 | I26: =IFERROR(J26/$H$18*1000000,0) -> -63569.75 | J26: ='DB1'!J26+'DB2'!J26 -> -8458.3441 | L26: КОМИССИИ | R26: СРОК СМР | U26: =(U27-U25)/(365/4) -> 16
B27: ПОКУПКА ЛЬГОТЫ | H27: =IFERROR(J27/$G$18*1000000,0) -> 22313.699 | I27: =IFERROR(J27/$H$18*1000000,0) -> 35242.985 | J27: ='DB1'!J27+'DB2'!J27 -> 4689.2948 | L27: РЕЗЕРВИРОВАНИЕ в банке | O27: =(P31+P32+P33)*P27 -> 303.39455 | P27: 0.005 | R27: РНВ 2 | U27: ='DB2'!U27 -> 47756
B28: РАССРОЧКА ВРИ | H28: =IFERROR(J28/$G$18*1000000,0) -> 0 | I28: =IFERROR(J28/$H$18*1000000,0) -> 0 | J28: ='DB1'!J28+'DB2'!J28 -> 0 | L28: БРОКЕРИДЖ МРГ бридж | O28: =(P31+P32)*P28 -> 0 | P28: 0 | R28: ОКОНЧАНИЕ ПРОДАЖ | U28: =_xlfn.MAXIFS(CF!$F$6:$BM$6,CF!$F$9:$BM$9,">0") -> 48213
B29: АРЕНДА ЗУ/НАЛОГ ЗУ | F29: =P49 -> АРЕНДА | H29: =IFERROR(J29/$G$18*1000000,0) -> 1122.6079 | I29: =IFERROR(J29/$H$18*1000000,0) -> 1773.0836 | J29: ='DB1'!J29+'DB2'!J29 -> 235.91962 | L29: БРОКЕРИДЖ МРГ проектное фин-ие | O29: =(P33+P32)*P29 -> 0 | R29: СРОК | U29: =(U28-U23)/365 -> 6.7534247
B30: ВЛОЖЕНИЯ В СТРОИТЕЛЬСТВО | H30: =IFERROR(J30/$G$18*1000000,0) -> 185503.48 | I30: =IFERROR(J30/$H$18*1000000,0) -> 292990.25 | J30: ='DB1'!J30+'DB2'!J30 -> 38984.146 | L30: ОБЪЕМ ФИНАНСИРОВАНИЯ
B31: ПРОЕКТИРОВАНИЕ (К+П+РД) | F31: =H31 -> 7310.4316 | G31: м2 S общ. | H31: =IFERROR(J31/$G$18*1000000,0) -> 7310.4316 | I31: =IFERROR(J31/$H$18*1000000,0) -> 11546.334 | J31: ='DB1'!J31+'DB2'!J31 -> 1536.3104 | L31: ВХОД | O31: млн. руб. | P31: ='DB1'!P31+'DB2'!P31 -> 0 | R31: РЕЗУЛЬТАТ
B32: СОГЛАСОВАНИЯ | F32: =H32 -> 1000 | G32: м2 S общ. | H32: =IFERROR(J32/$G$18*1000000,0) -> 1000 | I32: =IFERROR(J32/$H$18*1000000,0) -> 1579.4327 | J32: ='DB1'!J32+'DB2'!J32 -> 210.15318 | L32: ДО РНС | O32: млн. руб. | P32: ='DB1'!P32+'DB2'!P32 -> 9723.0277 | U32: млн. руб.
B33: СМР жилье | F33: 137000 | G33: м2 S общ. | H33: =IFERROR(J33/(G18)*1000000,0) -> 137000 | I33: =IFERROR(J33/($H$8+$H$9+$H$11+$H$16)*1000000,0) -> 216382.27 | J33: ='DB1'!J33+'DB2'!J33 -> 28790.985 | L33: ПРОЕКТНОЕ ФИН-ИЕ (без учета реф бриджа) | O33: млн. руб. | P33: ='DB1'!P33+'DB2'!P33 -> 50955.882 | R33: ДОХОДЫ | U33: ='DB1'!U33+'DB2'!U33 -> 78746.093
B34: СМР офисы | F34: =H34 -> 0 | G34: м2 S общ. | H34: =IFERROR(J34/($G$10+$G$17)*1000000,0) -> 0 | I34: =IFERROR(J34/($H$10+$H$17)*1000000,0) -> 0 | J34: ='DB1'!J34+'DB2'!J34 -> 0 | L34: % и КОМИСИИ банка | O34: млн. руб. | P34: ='DB1'!P34+'DB2'!P34 -> 10379.811 | R34: РАСХОДЫ НА ПРОДАЖУ | U34: ='DB1'!U34+'DB2'!U34 -> -5999.3951
B35: СМР ТЦ | F35: =H35 -> 0 | G35: м2 S общ. | H35: =IFERROR(J35/$G$12*1000000,0) -> 0 | I35: =IFERROR(J35/$H$12*1000000,0) -> 0 | J35: ='DB1'!J35+'DB2'!J35 -> 0 | M35: бридж | O35: млн. руб. | P35: ='DB1'!P35+'DB2'!P35 -> 1452.0383 | R35: ИНВЕСТИЦИИ | U35: ='DB1'!U35+'DB2'!U35 -> -47750.706
B36: СМР соц. объектов (компенсация) | F36: =H36 -> 20790.73 | G36: м2 Sобщ. | H36: =IFERROR(J36/(G18)*1000000,0) -> 20790.73 | I36: =IFERROR(J36/(H18)*1000000,0) -> 32837.558 | J36: ='DB1'!J36+'DB2'!J36 -> 4369.2379 | M36: проектное фин-ие | O36: млн. руб. | P36: ='DB1'!P36+'DB2'!P36 -> 8624.3786 | R36: ПРОЦЕНТЫ | U36: ='DB1'!U36+'DB2'!U36 -> -10772.116
B37: ОТДЕЛКА жилье | F37: =I37 -> 0 | G37: м2 Sпол. | H37: =IFERROR(J37/($G$8+$G$9)*1000000,0) -> 0 | I37: =IFERROR(J37/($H$8+$H$9)*1000000,0) -> 0 | J37: ='DB1'!J37+'DB2'!J37 -> 0 | M37: комиссии банка | O37: млн. руб. | P37: ='DB1'!P37+'DB2'!P37 -> 303.39455 | R37: НАЛОГИ | U37: ='DB1'!U37+'DB2'!U37 -> -4878.3251
B38: ='DB1'!B38 -> СОДЕРЖАНИЕ ПЛОЩАДКИ | F38: =H38 -> 770.14386 | G38: м2 S общ. | H38: =IFERROR(J38/$G$18*1000000,0) -> 770.14386 | I38: =IFERROR(J38/$H$18*1000000,0) -> 1216.3904 | J38: ='DB1'!J38+'DB2'!J39 -> 161.84818 | L38: АКЦИОНЕРВНЫЕ ЗАЙМЫ | R38: ПРИБЫЛЬ ( в т ч SF МРГ) | U38: ='DB1'!U38+'DB2'!U38 -> 9345.5509
B39: СЕТИ | F39: 5500 | G39: м2 Sобщ. | H39: =IFERROR(J39/$G$18*1000000,0) -> 5500 | I39: =IFERROR(J39/$H$18*1000000,0) -> 8686.8796 | J39: ='DB1'!J39+'DB2'!J38 -> 1155.8425 | L39: СТАВКА ЗАЙМА | N39: 0.01 | P39: =P22+N39 -> 0.21 | R39: МАРЖИНАЛЬНОСТЬ до Н/О | U39: =(U38-CF!E146)/U33 -> 0.17534919
B40: МОНИТОРИНГИ | F40: =H40 -> 2500 | G40: м2 Sобщ. | H40: =IFERROR(J40/$G$18*1000000,0) -> 2500 | I40: =IFERROR(J40/$H$18*1000000,0) -> 3948.5816 | J40: ='DB1'!J40+'DB2'!J40 -> 525.38294 | L40: ТЕЛО ЗАЙМА | O40: млн. руб. | P40: ='DB1'!P40+'DB2'!P40 -> 596.3444 | R40: МАРЖ-СТЬ после Н/О | U40: =U38/U33 -> 0.11867955
B41: УПРАВЛЕНИЕ ПРОЕКТОМ | D41: =J41/(DETAILS!F361*3) -> 20.824864 | E41: млн. в мес. | F41: 0.04 | G41: % от расходов | H41: =IFERROR(J41/$G$18*1000000,0) -> 7134.7493 | I41: =IFERROR(J41/$H$18*1000000,0) -> 11268.856 | J41: ='DB1'!J41+'DB2'!J41 -> 1499.3902 | K41: =(J43+J53-U36-J50-J41)*3.5% -> 2172.7256 | L41: % | O41: млн. руб. | P41: ='DB1'!P41+'DB2'!P41 -> 392.30429 | R41: IRR ПРОЕКТА (pre-tax) | U41: =IFERROR(POWER((1+IRR(CF!F95:BM95,0.01)),4)-1,0) -> 0.1755044
B42: НЕПРЕДВИДЕННЫЕ РАСХОДЫ | F42: =J42/SUM(J31:J40) -> 0.02 | G42: % от расходов | H42: =IFERROR(J42/$G$18*1000000,0) -> 3497.4261 | I42: =IFERROR(J42/$H$18*1000000,0) -> 5523.949 | J42: ='DB1'!J42+'DB2'!J42 -> 734.9952 | K42: =J41/(J43+J53-U36-J50-J41) -> 0.024153376 | L42: ПРОЦЕНТЫ | N42: =IFERROR(P42/$G$18*1000000,0) -> 51258.401 | O42: =IFERROR(P42/$H$18*1000000,0) -> 80959.192 | P42: =-U36 -> 10772.116 | R42: IRR ИНВЕСТОРА | U42: =IFERROR(POWER((1+IRR(CF!F190:BM190,0.01)),4)-1,0) -> 0.63323675
B43: ИНВЕСТИЦИИ | H43: =IFERROR(J43/$G$18*1000000,0) -> 227218.58 | I43: =IFERROR(J43/$H$18*1000000,0) -> 358876.44 | J43: =SUM(J22,J24,J30) -> 47750.706 | R43: LLSR | U43: =(-U33-U37)/(U36-P33) -> 1.1966655
R44: PV | S44: =((1+T44)^(1/4))-1 -> 0.046635139 | T44: 0.2 | U44: =NPV(S44,CF!F190:BM190) -> 1866.4393
...

Sheet DB1
B2: ПРОЕКТ | C2: =DB!C2 -> КАСАТКИНА | E2: ОЧЕРЕДЬ | F2: 1 | G2: ЗУ | H2: =P48 -> 77:02:0019010:102 | L2: ПЛОЩАДЬ ЗУ | M2: =P51/10000 -> 2.544 | O2: ПЛОТНОСТЬ | P2: =DB!P2 -> 35000 | Q2: АДРЕС | R2: =DB!R2 -> ул. КАСАТКИНА, ВЛ. 7 | U2: =DB!U2 -> 45826
B5: ТЭПы | F5: стены = | G5: =DB!$G$5 -> 0.07 | L5: ДОХОДЫ
F6: ГНС | G6: ОБЩАЯ ПЛОЩАДЬ | H6: ПОЛЕЗНАЯ ПЛОЩАДЬ | I6: LF, % | J6: КОЛ-ВО | P6: ЦЕНА → | Q6: ЦЕНА ← | R6: СРЕДНЯЯ ЦЕНА | S6: ДОХОД, млн. руб. | T6: % | U6: ОБЪЕМ ПРОДАЖ, в кв.
B7: НАЗЕМНАЯ ЧАСТЬ | E7: S лота | F7: =F8+F11 -> 96326 | G7: =SUM(G8:G14) -> 89583.18 | H7: =SUM(H8:H14) -> 62942.716 | I7: =IFERROR(1-H7/G7,"") -> 0.29738243 | L7: =B7 -> НАЗЕМНАЯ ЧАСТЬ | M7: старт | N7: % пост. | O7: дисконт
A8: ЖИЛАЯ | B8: КВАРТИРЫ | D8: =F8/$F$7 -> 0.94764861 | E8: =DB!E8 -> 53 | F8: =IF('МАСТЕР ПЛАН'!$AE$2=TRUE,'МАСТЕР ПЛАН'!AB5,IF('МАСТЕР ПЛАН'!$AE$11=TRUE,'МАСТЕР ПЛАН'!AB14,IF('МАСТЕР ПЛАН'!$AE$19=TRUE,'МАСТЕР ПЛАН'!AB22,IF('МАСТЕР ПЛАН'!$AE$28=TRUE,'МАСТЕР ПЛАН'!AB31,0)))) -> 91283.2 | G8: =F8*(1-$G$5) -> 84893.376 | H8: =G8*(1-I8) -> 59425.363 | I8: =DB!$I8 -> 0.3 | J8: =IFERROR(ROUND(H8/E8,0),0) -> 1121 | L8: =B8 -> КВАРТИРЫ | M8: =$U$25 -> 46296 | N8: 0.7 | O8: -0.17 | P8: =_xlfn.MINIFS('CF1'!$F17:$AS17,'CF1'!$F8:$AS8,">0") -> 522.9 | Q8: =_xlfn.MAXIFS('CF1'!$F17:$AS17,'CF1'!$F8:$AS8,">0") -> 698.37097 | R8: =DB!R8 -> 630 | S8: ='CF1'!E26 -> 37437.979 | T8: =S8/$S$18 -> 0.87891604 | U8: 3000
A9: ЖИЛАЯ | B9: АПАРТАМЕНТЫ | D9: =F9/$F$7 -> 0 | E9: 60 | G9: =F9*(1-$G$5) -> 0 | H9: =G9*(1-I9) -> 0 | I9: =DB!$I9 -> 0 | J9: =IFERROR(ROUND(H9/E9,0),0) -> 0 | L9: =B9 -> АПАРТАМЕНТЫ | M9: =$U$25 -> 46296 | N9: 0.7 | P9: =_xlfn.MINIFS('CF1'!$F18:$AS18,'CF1'!$F9:$AS9,">0") -> 0 | Q9: =_xlfn.MAXIFS('CF1'!$F18:$AS18,'CF1'!$F9:$AS9,">0") -> 0 | S9: ='CF1'!E27 -> 0 | T9: =S9/$S$18 -> 0
A10: НЕЖИЛАЯ | B10: ОФИСЫ | D10: =F10/$F$7 -> 0 | E10: 100 | G10: =F10*(1-$G$5) -> 0 | H10: =G10*(1-I10) -> 0 | I10: =DB!$I10 -> 0 | J10: =IFERROR(ROUND(H10/E10,0),0) -> 0 | L10: =B10 -> ОФИСЫ | M10: =$U$25 -> 46296 | N10: 0.7 | P10: =_xlfn.MINIFS('CF1'!$F19:$AS19,'CF1'!$F10:$AS10,">0") -> 0 | Q10: =_xlfn.MAXIFS('CF1'!$F19:$AS19,'CF1'!$F10:$AS10,">0") -> 0 | S10: ='CF1'!E28 -> 0 | T10: =S10/$S$18 -> 0
A11: ТОРГОВЛЯ | B11: РИТЕЙЛ | D11: =F11/$F$7 -> 0.05235139 | E11: 100 | F11: =IF('МАСТЕР ПЛАН'!$AE$2=TRUE,'МАСТЕР ПЛАН'!AB6,IF('МАСТЕР ПЛАН'!$AE$11=TRUE,'МАСТЕР ПЛАН'!AB15,IF('МАСТЕР ПЛАН'!$AE$19=TRUE,'МАСТЕР ПЛАН'!AB23,IF('МАСТЕР ПЛАН'!$AE$28=TRUE,'МАСТЕР ПЛАН'!AB32,0)))) -> 5042.8 | G11: =F11*(1-$G$5) -> 4689.804 | H11: =G11*(1-I11) -> 3517.353 | I11: =DB!$I11 -> 0.25 | J11: =IFERROR(ROUND(H11/E11,0),0) -> 35 | L11: =B11 -> РИТЕЙЛ | M11: =DB!$M$11 -> 1 | N11: 1 | O11: =Q11/P11-1 -> 0 | P11: =_xlfn.MINIFS('CF1'!$F20:$AS20,'CF1'!$F11:$AS11,">0") -> 700 | Q11: =_xlfn.MAXIFS('CF1'!$F20:$AS20,'CF1'!$F11:$AS11,">0") -> 700 | R11: 700 | S11: ='CF1'!E29 -> 2462.1471 | T11: =S11/$S$18 -> 0.057802815
A12: ТОРГОВЛЯ | B12: ТЦ | D12: =F12/$F$7 -> 0 | E12: 100 | G12: =F12*(1-$G$5) -> 0 | H12: =G12*(1-I12) -> 0 | I12: =DB!$I12 -> 0 | J12: =IFERROR(ROUND(H12/E12,0),0) -> 0 | L12: =B12 -> ТЦ | M12: =DB!$M$12 -> 0 | P12: =_xlfn.MINIFS('CF1'!$F21:$AS21,'CF1'!$F12:$AS12,">0") -> 0 | Q12: =_xlfn.MAXIFS('CF1'!$F21:$AS21,'CF1'!$F12:$AS12,">0") -> 0 | S12: ='CF1'!E30 -> 0 | T12: =S12/$S$18 -> 0
A13: ='TS1'!B68 -> СОЦИАЛКА | B13: ШКОЛА | C13: мест | G13: =F13*(1-$G$5) -> 0 | L13: =B13 -> ШКОЛА
A14: =A13 -> СОЦИАЛКА | B14: ДОУ | C14: мест | G14: =F14*(1-$G$5) -> 0 | L14: =B14 -> ДОУ
B15: ПОДЗЕМНАЯ ЧАСТЬ | D15: S общ. | E15: S пол. | G15: =G16 -> 23960 | H15: =H16 -> 8985 | L15: =B15 -> ПОДЗЕМНАЯ ЧАСТЬ
B16: ПАРКИНГ ЖИЛЬЕ | C16: =J16/J8 -> 0.53434434 | D16: =DB!D16 -> 40 | E16: =DB!E16 -> 15 | G16: =J16*D16 -> 23960 | H16: =J16*E16 -> 8985 | J16: =ROUNDUP((J8*2.1*0.257*0.9)*1.1,0) -> 599 | L16: =B16 -> ПАРКИНГ ЖИЛЬЕ | N16: =DB!N16 -> 0.7 | P16: =_xlfn.MINIFS('CF1'!$F22:$AS22,'CF1'!$F13:$AS13,">0") -> 4500 | Q16: =_xlfn.MAXIFS('CF1'!$F22:$AS22,'CF1'!$F13:$AS13,">0") -> 4500 | R16: 4500 | S16: ='CF1'!E31 -> 2695.5 | T16: =S16/$S$18 -> 0.063281145
B17: ПАРКИНГ ОФИС | C17: =DB!C17 -> 0 | D17: =DB!D17 -> 0 | E17: =DB!E17 -> 0 | G17: =J17*D17 -> 0 | H17: =J17*E17 -> 0 | J17: =IFERROR(ROUND(J10*C17,0),0) -> 0 | L17: =B17 -> ПАРКИНГ ОФИС | P17: =_xlfn.MINIFS('CF1'!$F23:$AS23,'CF1'!$F14:$AS14,">0") -> 0 | Q17: =_xlfn.MAXIFS('CF1'!$F23:$AS23,'CF1'!$F14:$AS14,">0") -> 0 | S17: ='CF1'!E32 -> 0 | T17: =S17/$S$18 -> 0
B18: ПЛОЩАДИ | F18: =F7 -> 96326 | G18: =G15+G7 -> 113543.18 | H18: =SUM(H7,H15) -> 71927.716 | I18: =I7 -> 0.29738243 | L18: ДОХОДЫ | S18: =SUM(S8:S17) -> 42595.626
B20: ИНВЕСТИЦИИ | L20: ФИНАНСИРОВАНИЕ | R20: СРОКИ
H21: руб./S общ. | I21: руб./S пол. | J21: млн.руб. | L21: КРЕДИТ | U21: кв.
B22: ВХОД | F22: =J22/M2 -> 1303.0054 | G22: за Га | H22: =IFERROR(J22/$G$18*1000000,0) -> 29194.583 | I22: =IFERROR(J22/$H$18*1000000,0) -> 46085.792 | J22: =-SUMIFS(DETAILS!$I$138:$I$146,DETAILS!$C$138:$C$146,'DB1'!F2)/10^6 -> 3314.8458 | L22: СТАВКИ | P22: ='TS1'!J85 -> 0.2 | R22: НАЧАЛО РАСЧЕТОВ | U22: =DB!U22 -> 45017
B23: FINDERS FEE | G23: % от входа | H23: =IFERROR(J23/$G$18*1000000,0) -> 0 | I23: =IFERROR(J23/$H$18*1000000,0) -> 0 | J23: =F23*J22 -> 0 | L23: СТАВКА бридж | N23: =DB!N23 -> 0.05 | P23: =P22+N23 -> 0.25 | R23: НАЧАЛО ПРОЕКТА | U23: =DB!U23 -> 45748
B24: ЗЕМЕЛЬНО-ПРАВОВЫЕ ВОПРОСЫ | H24: =J24/$G$18*1000000 -> 25151.91 | I24: =IFERROR(J24/$H$18*1000000,0) -> 39704.136 | J24: =SUM(J25:J29) -> 2855.8278 | L24: СТАВКА проектное фин-ие | N24: =DB!N24 -> 0.038 | P24: =P22+N24 -> 0.238 | R24: СРОК ИРД | U24: 6
B25: ВРИ | C25: =IF(D25>0,"со скидкой",0) -> 0 | D25: ='TS1'!E76 -> 0 | H25: =IFERROR(J25/$G$18*1000000,0) -> 40131.177 | I25: =IFERROR(J25/$H$18*1000000,0) -> 63350.009 | J25: ='TS1'!E77/10^6 -> 4556.6214 | L25: СТАВКА под эскроу | P25: =DB!P25 -> 0.038 | R25: РНС | U25: =EOMONTH(_xlfn.MINIFS('TS1'!$F$17:$AS$17,'TS1'!$F$25:$AS$25,">0"),-3)+1 -> 46296
B26: ЛЬГОТА | H26: =IFERROR(J26/$G$18*1000000,0) -> -40131.177 | I26: =IFERROR(J26/$H$18*1000000,0) -> -63350.009 | J26: =-'TS1'!C81/10^6 -> -4556.6214 | L26: КОМИССИИ | R26: СРОК СМР | U26: 12
B27: ПОКУПКА ЛЬГОТЫ | H27: =IFERROR(J27/$G$18*1000000,0) -> 24078.706 | I27: =IFERROR(J27/$H$18*1000000,0) -> 38010.005 | J27: ='TS1'!AA113+'TS1'!AC113 -> 2733.9729 | L27: РЕЗЕРВИРОВАНИЕ в банке | O27: =(P31+P32+P33)*P27 -> 166.85488 | P27: 0.005 | R27: РНВ | U27: =_xlfn.MINIFS('TS1'!$F$17:$AS$17,'TS1'!$F$16:$AS$16,'DB1'!R27) -> 47391
B28: РАССРОЧКА ВРИ | H28: =IFERROR(J28/$G$18*1000000,0) -> 0 | I28: =IFERROR(J28/$H$18*1000000,0) -> 0 | J28: ='TS1'!N67 -> 0 | L28: БРОКЕРИДЖ МРГ бридж | O28: =(P31+P32)*P28 -> 0 | P28: 0 | R28: ОКОНЧАНИЕ ПРОДАЖ | U28: =_xlfn.MAXIFS('TS1'!$F$36:$AS$36,'TS1'!$F$38:$AS$38,">0") -> 48121
B29: АРЕНДА ЗУ/НАЛОГ ЗУ | F29: =P49 -> АРЕНДА | H29: =IFERROR(J29/$G$18*1000000,0) -> 1073.2036 | I29: =IFERROR(J29/$H$18*1000000,0) -> 1694.1306 | J29: =-'CF1'!E62 -> 121.85494 | L29: БРОКЕРИДЖ МРГ проектное фин-ие | O29: =(P33+P32)*P29 -> 0 | R29: СРОК | U29: =(U28-U23)/365 -> 6.5013699
B30: ВЛОЖЕНИЯ В СТРОИТЕЛЬСТВО | H30: =IFERROR(J30/$G$18*1000000,0) -> 167175.27 | I30: =IFERROR(J30/$H$18*1000000,0) -> 263898.44 | J30: =SUM(J31:J42) -> 18981.612 | L30: ОБЪЕМ ФИНАНСИРОВАНИЯ
B31: ПРОЕКТИРОВАНИЕ (К+П+РД) | F31: 8000 | G31: м2 S общ. | H31: =IFERROR(J31/$G$18*1000000,0) -> 8000 | I31: =IFERROR(J31/$H$18*1000000,0) -> 12628.587 | J31: =$G$18*F31/10^6 -> 908.34544 | L31: ВХОД | O31: млн. руб. | P31: =-'CF1'!F60 -> 0 | R31: РЕЗУЛЬТАТ
B32: СОГЛАСОВАНИЯ | F32: 1000 | G32: м2 S общ. | H32: =IFERROR(J32/$G$18*1000000,0) -> 1000 | I32: =IFERROR(J32/$H$18*1000000,0) -> 1578.5734 | J32: =$G$18*F32/10^6 -> 113.54318 | L32: ДО РНС | O32: млн. руб. | P32: =-SUMIFS('CF1'!$F$50:$BM$50,'CF1'!$F$5:$BM$5,"<"&(EOMONTH('DB1'!U25,2)))-SUMIFS('CF1'!$F$59:$BM$59,'CF1'!$F$5:$BM$5,"<"&(EOMONTH('DB1'!U25,2)))-P31 -> 6630.9834 | U32: млн. руб.
B33: СМР жилье | D33: ДГП | E33: =-DETAILS!G288 -> 126510.6 | F33: =DB!F33 -> 137000 | G33: м2 S общ. | H33: =IFERROR(J33/($G$8+$G$9+$G$11+$G$16)*1000000,0) -> 137000 | I33: =IFERROR(J33/($H$8+$H$9+$H$11+$H$16)*1000000,0) -> 216264.56 | J33: =($G$16+$G$11+$G$9+$G$8)*F33/10^6 -> 15555.416 | L33: ПРОЕКТНОЕ ФИН-ИЕ (без учета реф бриджа) | O33: млн. руб. | P33: =-SUMIFS('CF1'!$F$50:$BM$50,'CF1'!$F$5:$BM$5,"<="&'DB1'!U27)-SUMIFS('CF1'!$F$59:$BM$59,'CF1'!$F$5:$BM$5,"<="&'DB1'!U27)-P31 -> 26739.992 | R33: ДОХОДЫ | U33: ='CF1'!E34 -> 42595.626
B34: СМР офисы | F34: 0 | G34: м2 S общ. | H34: =IFERROR(J34/($G$10+$G$17)*1000000,0) -> 0 | I34: =IFERROR(J34/($H$10+$H$17)*1000000,0) -> 0 | J34: =($G$10+$G$17)*F34/10^6 -> 0 | L34: % и КОМИСИИ банка | O34: млн. руб. | P34: ='CF1'!E90+'CF1'!E92+'CF1'!E98+'CF1'!E100+O27 -> 6741.8259 | R34: РАСХОДЫ НА ПРОДАЖУ | U34: ='CF1'!E50 -> -3239.0461
B35: СМР ТЦ | F35: 0 | G35: м2 S общ. | H35: =IFERROR(J35/$G$12*1000000,0) -> 0 | I35: =IFERROR(J35/$H$12*1000000,0) -> 0 | J35: =$G$12*F35/10^6 -> 0 | M35: бридж | O35: млн. руб. | P35: ='CF1'!E90+'CF1'!E92 -> 1068.6792 | R35: ИНВЕСТИЦИИ | U35: ='CF1'!E59 -> -25152.286
B36: СМР соц. объектов (компенсация) | F36: 0 | G36: м2 Sобщ. | H36: =IFERROR(J36/($G$7+$G$15)*1000000,0) -> 2593.5845 | I36: =IFERROR(J36/($H$8+$H$9+$H$11+$H$16)*1000000,0) -> 4094.1635 | J36: =-'CF1'!E68 -> 294.48383 | M36: проектное фин-ие | O36: млн. руб. | P36: ='CF1'!E98+'CF1'!E100 -> 5506.2918 | R36: ПРОЦЕНТЫ | U36: ='CF1'!E85+'CF1'!E91+'CF1'!E93+'CF1'!E99+'CF1'!E101+'CF1'!E104 -> -6991.9295
B37: ОТДЕЛКА жилье | F37: 0 | G37: м2 Sпол. | H37: =IFERROR(J37/($G$8+$G$9)*1000000,0) -> 0 | I37: =IFERROR(J37/($H$8+$H$9)*1000000,0) -> 0 | J37: =($H$8+$H$9)*F37/10^6 -> 0 | M37: комиссии банка | O37: млн. руб. | P37: ='CF1'!E103 -> 166.85488 | R37: НАЛОГИ | U37: ='CF1'!E111 -> -2244.3118
B38: СОДЕРЖАНИЕ ПЛОЩАДКИ | F38: 1000 | G38: м2 S общ. | H38: =IFERROR(J38/$G$18*1000000,0) -> 1000 | I38: =IFERROR(J38/$H$18*1000000,0) -> 1578.5734 | J38: =$G$18*F38/10^6 -> 113.54318 | L38: АКЦИОНЕРВНЫЕ ЗАЙМЫ | R38: ПРИБЫЛЬ ( в т ч SF МРГ) | U38: =SUM(U33:U37) -> 4968.0526
B39: СЕТИ | F39: =DB!F39 -> 5500 | G39: м2 Sобщ. | H39: =IFERROR(J39/$G$18*1000000,0) -> 5500 | I39: =IFERROR(J39/$H$18*1000000,0) -> 8682.1537 | J39: =$G$18*F39/10^6 -> 624.48749 | L39: СТАВКА ЗАЙМА | N39: 0.01 | P39: =P22+N39 -> 0.21 | R39: МАРЖИНАЛЬНОСТЬ до Н/О | U39: =(U38-'CF1'!E127)/U33 -> 0.16324891
B40: МОНИТОРИНГИ | D40: =MIN('CF1'!$F$72:$BM$72)/-3 -> 6.329691 | E40: млн. в мес. | F40: 2500 | G40: м2 Sобщ. | H40: =IFERROR(J40/$G$18*1000000,0) -> 2500 | I40: =IFERROR(J40/$H$18*1000000,0) -> 3946.4335 | J40: =$G$18*F40/10^6 -> 283.85795 | L40: ТЕЛО ЗАЙМА | O40: млн. руб. | P40: ='CF1'!E81 -> 382.3901 | R40: МАРЖ-СТЬ после Н/О | U40: =U38/U33 -> 0.11663293
B41: УПРАВЛЕНИЕ ПРОЕКТОМ | D41: =J41/('TS1'!D33*3) -> 12.1677 | E41: млн. в мес. | F41: =DB!F41 -> 0.04 | G41: % от расходов | H41: =IFERROR(J41/$G$18*1000000,0) -> 6429.8182 | I41: =IFERROR(J41/$H$18*1000000,0) -> 10149.94 | J41: =SUM($J$31:$J$40,J42)*$F41 -> 730.06201 | K41: =(J43+J53-U36-J50-J41)*3.5% -> 1194.9718 | L41: % | O41: млн. руб. | P41: ='CF1'!E84 -> 250.10365 | R41: IRR ПРОЕКТА (pre-tax) | U41: =IFERROR(POWER((1+IRR('CF1'!F76:BM76,0.01)),4)-1,0) -> 0.17185456
B42: НЕПРЕДВИДЕННЫЕ РАСХОДЫ | F42: 0.02 | G42: % от расходов | H42: =IFERROR(J42/$G$18*1000000,0) -> 3151.8717 | I42: =IFERROR(J42/$H$18*1000000,0) -> 4975.4608 | J42: =SUM($J$31:$J$40)*$F42 -> 357.87353 | K42: =J41/(J43+J53-U36-J50-J41) -> 0.021383074 | L42: ПРОЦЕНТЫ | N42: =P42/$G$18*1000000 -> 61579.476 | O42: =P42/$H$18*1000000 -> 97207.723 | P42: =-U36 -> 6991.9295 | R42: IRR ИНВЕСТОРА | U42: =IFERROR(POWER((1+IRR('CF1'!F171:BM171,0.01)),4)-1,0) -> 0.59770527
B43: ИНВЕСТИЦИИ | H43: =IFERROR(J43/$G$18*1000000,0) -> 221521.77 | I43: =IFERROR(J43/$H$18*1000000,0) -> 349688.37 | J43: =SUM(J22,J24,J30) -> 25152.286 | R43: LLSR | U43: =(-U33-U37)/(U36-P33) -> 1.1962353
B45: РАСХОДЫ НА ПРОДАЖУ
...

Sheet DB2
B2: ПРОЕКТ | C2: =DB!C2 -> КАСАТКИНА | E2: ОЧЕРЕДЬ | F2: 2 | G2: ЗУ | H2: =P48 -> 77:02:0019010:102 | L2: ПЛОЩАДЬ ЗУ | M2: =P51/10000 -> 2.218 | O2: ПЛОТНОСТЬ | P2: =DB!P2 -> 35000 | Q2: АДРЕС | R2: =DB!R2 -> ул. КАСАТКИНА, ВЛ. 7 | U2: =DB!U2 -> 45826
B5: ТЭПы | F5: стены = | G5: =DB!$G$5 -> 0.07 | L5: ДОХОДЫ
F6: ГНС | G6: ОБЩАЯ ПЛОЩАДЬ | H6: ПОЛЕЗНАЯ ПЛОЩАДЬ | I6: LF, % | J6: КОЛ-ВО | P6: ЦЕНА → | Q6: ЦЕНА ← | R6: СРЕДНЯЯ ЦЕНА | S6: ДОХОД, млн. руб. | T6: % | U6: ОБЪЕМ ПРОДАЖ, в кв.
B7: НАЗЕМНАЯ ЧАСТЬ | E7: S лота | F7: =F8+F11 -> 81817.2 | G7: =SUM(G8:G14) -> 76089.996 | H7: =SUM(H8:H14) -> 53433.401 | I7: =IFERROR(1-H7/G7,"") -> 0.2977605 | L7: =B7 -> НАЗЕМНАЯ ЧАСТЬ | M7: старт | N7: % пост. | O7: дисконт
A8: ЖИЛАЯ | B8: КВАРТИРЫ | C8: =ROUND(J8*2.1,0) -> 2016 | D8: =F8/F7 -> 0.95520991 | E8: =DB!E8 -> 53 | F8: =IF('МАСТЕР ПЛАН'!$AE$2=TRUE,'МАСТЕР ПЛАН'!AC5,IF('МАСТЕР ПЛАН'!$AE$11=TRUE,'МАСТЕР ПЛАН'!AC14,IF('МАСТЕР ПЛАН'!$AE$19=TRUE,'МАСТЕР ПЛАН'!AC22,IF('МАСТЕР ПЛАН'!$AE$28=TRUE,'МАСТЕР ПЛАН'!AC31,0)))) -> 78152.6 | G8: =F8*(1-$G$5) -> 72681.918 | H8: =G8*(1-I8) -> 50877.343 | I8: =DB!$I8 -> 0.3 | J8: =IFERROR(ROUND(H8/E8,0),0) -> 960 | L8: =B8 -> КВАРТИРЫ | M8: =$U$25 -> 46661 | N8: 0.7 | O8: -0.17 | P8: =_xlfn.MINIFS('CF2'!$F17:$AS17,'CF2'!$F8:$AS8,">0") -> 522.9 | Q8: =_xlfn.MAXIFS('CF2'!$F17:$AS17,'CF2'!$F8:$AS8,">0") -> 710.55666 | R8: ='DB1'!R8 -> 630 | S8: ='CF2'!E26 -> 32052.726 | T8: =S8/$S$18 -> 0.88664763 | U8: 3000
A9: ЖИЛАЯ | B9: АПАРТАМЕНТЫ | D9: =F9/$F$7 -> 0 | E9: 60 | G9: =F9*(1-$G$5) -> 0 | H9: =G9*(1-I9) -> 0 | I9: =DB!$I9 -> 0 | J9: =IFERROR(ROUND(H9/E9,0),0) -> 0 | L9: =B9 -> АПАРТАМЕНТЫ | M9: =$U$25 -> 46661 | N9: 0.7 | P9: =_xlfn.MINIFS('CF2'!$F18:$AS18,'CF2'!$F9:$AS9,">0") -> 0 | Q9: =_xlfn.MAXIFS('CF2'!$F18:$AS18,'CF2'!$F9:$AS9,">0") -> 0 | S9: ='CF2'!E27 -> 0 | T9: =S9/$S$18 -> 0
A10: НЕЖИЛАЯ | B10: ОФИСЫ | D10: =F10/$F$7 -> 0 | E10: 100 | G10: =F10*(1-$G$5) -> 0 | H10: =G10*(1-I10) -> 0 | I10: =DB!$I10 -> 0 | J10: =IFERROR(ROUND(H10/E10,0),0) -> 0 | L10: =B10 -> ОФИСЫ | M10: =$U$25 -> 46661 | N10: 0.7 | P10: =_xlfn.MINIFS('CF2'!$F19:$AS19,'CF2'!$F10:$AS10,">0") -> 0 | Q10: =_xlfn.MAXIFS('CF2'!$F19:$AS19,'CF2'!$F10:$AS10,">0") -> 0 | S10: ='CF2'!E28 -> 0 | T10: =S10/$S$18 -> 0
A11: ТОРГОВЛЯ | B11: РИТЕЙЛ | D11: =F11/F7 -> 0.044790093 | E11: 100 | F11: =IF('МАСТЕР ПЛАН'!$AE$2=TRUE,'МАСТЕР ПЛАН'!AC6,IF('МАСТЕР ПЛАН'!$AE$11=TRUE,'МАСТЕР ПЛАН'!AC15,IF('МАСТЕР ПЛАН'!$AE$19=TRUE,'МАСТЕР ПЛАН'!AC23,IF('МАСТЕР ПЛАН'!$AE$28=TRUE,'МАСТЕР ПЛАН'!AC32,0)))) -> 3664.6 | G11: =F11*(1-$G$5) -> 3408.078 | H11: =G11*(1-I11) -> 2556.0585 | I11: =DB!$I11 -> 0.25 | J11: =IFERROR(ROUND(H11/E11,0),0) -> 26 | L11: =B11 -> РИТЕЙЛ | M11: =DB!$M$11 -> 1 | N11: 1 | O11: =Q11/P11-1 -> 0 | P11: =_xlfn.MINIFS('CF2'!$F20:$AS20,'CF2'!$F11:$AS11,">0") -> 700 | Q11: =_xlfn.MAXIFS('CF2'!$F20:$AS20,'CF2'!$F11:$AS11,">0") -> 700 | R11: 700 | S11: ='CF2'!E29 -> 1789.2409 | T11: =S11/$S$18 -> 0.04949427
A12: ТОРГОВЛЯ | B12: ТЦ | D12: =F12/$F$7 -> 0 | E12: 100 | G12: =F12*(1-$G$5) -> 0 | H12: =G12*(1-I12) -> 0 | I12: =DB!$I12 -> 0 | J12: =IFERROR(ROUND(H12/E12,0),0) -> 0 | L12: =B12 -> ТЦ | M12: =DB!$M$12 -> 0 | P12: =_xlfn.MINIFS('CF2'!$F21:$AS21,'CF2'!$F12:$AS12,">0") -> 0 | Q12: =_xlfn.MAXIFS('CF2'!$F21:$AS21,'CF2'!$F12:$AS12,">0") -> 0 | S12: ='CF2'!E30 -> 0 | T12: =S12/$S$18 -> 0
A13: ='TS2'!B68 -> СОЦИАЛКА | B13: ШКОЛА | C13: мест | D13: 1000 | G13: =F13*(1-$G$5) -> 0 | L13: =B13 -> ШКОЛА
A14: =A13 -> СОЦИАЛКА | B14: ДОУ | C14: мест | G14: =F14*(1-$G$5) -> 0 | L14: =B14 -> ДОУ
B15: ПОДЗЕМНАЯ ЧАСТЬ | D15: S общ. | E15: S пол. | G15: =G16 -> 20520 | H15: =H16 -> 7695 | L15: =B15 -> ПОДЗЕМНАЯ ЧАСТЬ
B16: ПАРКИНГ ЖИЛЬЕ | C16: =J16/J8 -> 0.534375 | D16: =DB!D16 -> 40 | E16: =DB!E16 -> 15 | G16: =J16*D16 -> 20520 | H16: =J16*E16 -> 7695 | J16: =ROUNDUP((J8*2.1*0.257*0.9)*1.1,0) -> 513 | L16: =B16 -> ПАРКИНГ ЖИЛЬЕ | N16: =DB!N16 -> 0.7 | P16: =_xlfn.MINIFS('CF2'!$F22:$AS22,'CF2'!$F13:$AS13,">0") -> 4500 | Q16: =_xlfn.MAXIFS('CF2'!$F22:$AS22,'CF2'!$F13:$AS13,">0") -> 4500 | R16: ='DB1'!R16 -> 4500 | S16: ='CF2'!E31 -> 2308.5 | T16: =S16/$S$18 -> 0.063858097
B17: ПАРКИНГ ОФИС | C17: =DB!C17 -> 0 | D17: =DB!D17 -> 0 | E17: =DB!E17 -> 0 | G17: =J17*D17 -> 0 | H17: =J17*E17 -> 0 | J17: =IFERROR(ROUND(J10*C17,0),0) -> 0 | L17: =B17 -> ПАРКИНГ ОФИС | P17: =_xlfn.MINIFS('CF2'!$F23:$AS23,'CF2'!$F14:$AS14,">0") -> 0 | Q17: =_xlfn.MAXIFS('CF2'!$F23:$AS23,'CF2'!$F14:$AS14,">0") -> 0 | S17: ='CF2'!E32 -> 0 | T17: =S17/$S$18 -> 0
B18: ПЛОЩАДИ | F18: =F7 -> 81817.2 | G18: =G15+G7 -> 96609.996 | H18: =SUM(H7,H15) -> 61128.401 | I18: =I7 -> 0.2977605 | L18: ДОХОДЫ | S18: =SUM(S8:S17) -> 36150.467
B20: ИНВЕСТИЦИИ | L20: ФИНАНСИРОВАНИЕ | R20: СРОКИ
H21: руб./S общ. | I21: руб./S пол. | J21: млн.руб. | L21: КРЕДИТ | U21: кв.
B22: ВХОД | F22: =J22/M2 -> 237.37601 | G22: за Га | H22: =IFERROR(J22/$G$18*1000000,0) -> 5449.7466 | I22: =IFERROR(J22/$H$18*1000000,0) -> 8613.0177 | J22: =-SUMIFS(DETAILS!$I$138:$I$146,DETAILS!$C$138:$C$146,'DB2'!F2)/10^6 -> 526.5 | L22: СТАВКИ | P22: ='TS2'!J85 -> 0.2 | R22: НАЧАЛО РАСЧЕТОВ | U22: =DB!U22 -> 45017
B23: FINDERS FEE | G23: % от входа | H23: =IFERROR(J23/$G$18*1000000,0) -> 0 | I23: =IFERROR(J23/$H$18*1000000,0) -> 0 | J23: =F23*J22 -> 0 | L23: СТАВКА бридж | N23: =DB!N23 -> 0.05 | P23: =P22+N23 -> 0.25 | R23: НАЧАЛО ПРОЕКТА | U23: =DB!U23 -> 45748
B24: ЗЕМЕЛЬНО-ПРАВОВЫЕ ВОПРОСЫ | H24: =J24/$G$18*1000000 -> 21420.005 | I24: =IFERROR(J24/$H$18*1000000,0) -> 33853.111 | J24: =SUM(J25:J29) -> 2069.3866 | L24: СТАВКА проектное фин-ие | N24: =DB!N24 -> 0.038 | P24: =P22+N24 -> 0.238 | R24: СРОК ИРД | U24: =5+4+1 -> 10
B25: ВРИ | C25: =IF(D25>0,"со скидкой",0) -> 0 | D25: ='TS2'!E76 -> 0 | H25: =IFERROR(J25/$G$18*1000000,0) -> 40386.325 | I25: =IFERROR(J25/$H$18*1000000,0) -> 63828.312 | J25: ='TS2'!E77/10^6 -> 3901.7227 | L25: СТАВКА под эскроу | P25: =DB!P25 -> 0.038 | R25: РНС | U25: =EOMONTH(_xlfn.MINIFS('TS2'!$F$17:$AS$17,'TS2'!$F$25:$AS$25,">0"),-3)+1 -> 46661
B26: ЛЬГОТА | H26: =IFERROR(J26/$G$18*1000000,0) -> -40386.325 | I26: =IFERROR(J26/$H$18*1000000,0) -> -63828.312 | J26: =-'TS2'!C81/10^6 -> -3901.7227 | L26: КОМИССИИ | R26: СРОК СМР | U26: 12
B27: ПОКУПКА ЛЬГОТЫ | H27: =IFERROR(J27/$G$18*1000000,0) -> 20239.333 | I27: =IFERROR(J27/$H$18*1000000,0) -> 31987.126 | J27: ='TS2'!AA113+'TS2'!AC113 -> 1955.3219 | L27: РЕЗЕРВИРОВАНИЕ в банке | O27: =(P31+P32+P33)*P27 -> 136.53967 | P27: 0.005 | R27: РНВ | U27: =_xlfn.MINIFS('TS2'!$F$17:$AS$17,'TS2'!$F$16:$AS$16,'DB2'!R27) -> 47756
B28: РАССРОЧКА ВРИ | H28: =IFERROR(J28/$G$18*1000000,0) -> 0 | I28: =IFERROR(J28/$H$18*1000000,0) -> 0 | J28: ='TS2'!N67 -> 0 | L28: БРОКЕРИДЖ МРГ бридж | O28: =(P31+P32)*P28 -> 0 | P28: 0 | R28: ОКОНЧАНИЕ ПРОДАЖ | U28: =_xlfn.MAXIFS('TS2'!$F$36:$AS$36,'TS2'!$F$38:$AS$38,">0") -> 48213
B29: АРЕНДА ЗУ/НАЛОГ ЗУ | F29: =P49 -> АРЕНДА | H29: =IFERROR(J29/$G$18*1000000,0) -> 1180.6715 | I29: =IFERROR(J29/$H$18*1000000,0) -> 1865.9849 | J29: =-'CF2'!E62 -> 114.06467 | L29: БРОКЕРИДЖ МРГ проектное фин-ие | O29: =(P33+P32)*P29 -> 0 | R29: СРОК | U29: =(U28-U23)/365 -> 6.7534247
B30: ВЛОЖЕНИЯ В СТРОИТЕЛЬСТВО | H30: =IFERROR(J30/$G$18*1000000,0) -> 207044.14 | I30: =IFERROR(J30/$H$18*1000000,0) -> 327221.6 | J30: =SUM(J31:J42) -> 20002.533 | L30: ОБЪЕМ ФИНАНСИРОВАНИЯ
B31: ПРОЕКТИРОВАНИЕ (П+РД) | F31: 6500 | G31: м2 S общ. | H31: =IFERROR(J31/$G$18*1000000,0) -> 6500 | I31: =IFERROR(J31/$H$18*1000000,0) -> 10272.884 | J31: =$G$18*F31/10^6 -> 627.96497 | L31: ВХОД | O31: млн. руб. | P31: =-'CF2'!F60 -> 0 | R31: РЕЗУЛЬТАТ
B32: СОГЛАСОВАНИЯ | F32: 1000 | G32: м2 S общ. | H32: =IFERROR(J32/$G$18*1000000,0) -> 1000 | I32: =IFERROR(J32/$H$18*1000000,0) -> 1580.4437 | J32: =$G$18*F32/10^6 -> 96.609996 | L32: ДО РНС | O32: млн. руб. | P32: =-SUMIFS('CF2'!$F$50:$BM$50,'CF2'!$F$5:$BM$5,"<"&(EOMONTH('DB2'!U25,2)))-SUMIFS('CF2'!$F$59:$BM$59,'CF2'!$F$5:$BM$5,"<"&(EOMONTH('DB2'!U25,2)))-P31 -> 3092.0443 | U32: млн. руб.
B33: СМР жилье | D33: ДГП | E33: =-DETAILS!G308 -> 128357 | F33: =DB!F33 -> 137000 | G33: м2 S общ. | H33: =IFERROR(J33/($G$8+$G$9+$G$11+$G$16)*1000000,0) -> 137000 | I33: =IFERROR(J33/($H$8+$H$9+$H$11+$H$16)*1000000,0) -> 216520.79 | J33: =($G$16+$G$11+$G$9+$G$8)*F33/10^6 -> 13235.569 | L33: ПРОЕКТНОЕ ФИН-ИЕ (без учета реф бриджа) | O33: млн. руб. | P33: =-SUMIFS('CF2'!$F$50:$BM$50,'CF2'!$F$5:$BM$5,"<="&'DB2'!U27)-SUMIFS('CF2'!$F$59:$BM$59,'CF2'!$F$5:$BM$5,"<="&'DB2'!U27)-P31 -> 24215.89 | R33: ДОХОДЫ | U33: ='CF2'!E34 -> 36150.467
B34: СМР офисы | F34: 0 | G34: м2 S общ. | H34: =IFERROR(J34/($G$10+$G$17)*1000000,0) -> 0 | I34: =IFERROR(J34/($H$10+$H$17)*1000000,0) -> 0 | J34: =($G$10+$G$17)*F34/10^6 -> 0 | L34: % и КОМИСИИ банка | O34: млн. руб. | P34: ='CF2'!E90+'CF2'!E92+'CF2'!E98+'CF2'!E100+O27 -> 3637.9856 | R34: РАСХОДЫ НА ПРОДАЖУ | U34: ='CF2'!E50 -> -2760.3491
B35: СМР ТЦ | F35: 0 | G35: м2 S общ. | H35: =IFERROR(J35/$G$12*1000000,0) -> 0 | I35: =IFERROR(J35/$H$12*1000000,0) -> 0 | J35: =$G$12*F35/10^6 -> 0 | M35: бридж | O35: млн. руб. | P35: ='CF2'!E90+'CF2'!E92 -> 383.35912 | R35: ИНВЕСТИЦИИ | U35: ='CF2'!E59 -> -22598.42
B36: СМР соц. объектов (компенсация) | F36: 0 | G36: м2 Sобщ. | H36: =IFERROR(J36/($G$7+$G$15)*1000000,0) -> 42177.355 | I36: =IFERROR(J36/($H$8+$H$9+$H$11+$H$16)*1000000,0) -> 66658.935 | J36: =-'CF2'!E68 -> 4074.7541 | M36: проектное фин-ие | O36: млн. руб. | P36: ='CF2'!E98+'CF2'!E100 -> 3118.0868 | R36: ПРОЦЕНТЫ | U36: ='CF2'!E85+'CF2'!E91+'CF2'!E93+'CF2'!E99+'CF2'!E101+'CF2'!E104 -> -3780.1862
B37: ОТДЕЛКА жилье | F37: 0 | G37: м2 Sпол. | H37: =IFERROR(J37/($G$8+$G$9)*1000000,0) -> 0 | I37: =IFERROR(J37/($H$8+$H$9)*1000000,0) -> 0 | J37: =($H$8+$H$9)*F37/10^6 -> 0 | M37: комиссии банка | O37: млн. руб. | P37: ='CF2'!E103 -> 136.53967 | R37: НАЛОГИ | U37: ='CF2'!E111 -> -2634.0133
B38: СЕТИ | F38: =DB!F39 -> 5500 | G38: м2 Sобщ. | H38: =IFERROR(J38/$G$18*1000000,0) -> 5500 | I38: =IFERROR(J38/$H$18*1000000,0) -> 8692.4403 | J38: =$G$18*F38/10^6 -> 531.35498 | L38: АКЦИОНЕРВНЫЕ ЗАЙМЫ | R38: ПРИБЫЛЬ ( в т ч SF МРГ) | U38: =SUM(U33:U37) -> 4377.4982
B39: СОДЕРЖАНИЕ ПЛОЩАДКИ | F39: 500 | G39: м2 S общ. | H39: =IFERROR(J39/$G$18*1000000,0) -> 500 | I39: =IFERROR(J39/$H$18*1000000,0) -> 790.22185 | J39: =$G$18*F39/10^6 -> 48.304998 | L39: СТАВКА ЗАЙМА | N39: 0.01 | P39: =P22+N39 -> 0.21 | R39: МАРЖИНАЛЬНОСТЬ до Н/О | U39: =(U38-'CF2'!E127)/U33 -> 0.1896068
B40: МОНИТОРИНГИ | D40: =MIN('CF2'!$F$72:$BM$72)/-3 -> 5.2442305 | E40: млн. в мес. | F40: 2500 | G40: м2 Sобщ. | H40: =IFERROR(J40/$G$18*1000000,0) -> 2500 | I40: =IFERROR(J40/$H$18*1000000,0) -> 3951.1092 | J40: =$G$18*F40/10^6 -> 241.52499 | L40: ТЕЛО ЗАЙМА | O40: млн. руб. | P40: ='CF2'!E81 -> 213.9543 | R40: МАРЖ-СТЬ после Н/О | U40: =U38/U33 -> 0.12109106
B41: УПРАВЛЕНИЕ ПРОЕКТОМ | D41: =J41/('TS2'!D33*3) -> 10.685114 | E41: млн. в мес. | F41: =DB!F41 -> 0.04 | G41: % от расходов | H41: =IFERROR(J41/$G$18*1000000,0) -> 7963.2361 | I41: =IFERROR(J41/$H$18*1000000,0) -> 12585.446 | J41: =SUM($J$31:$J$40,J42)*$F41 -> 769.32821 | K41: =(J43+J53-U36-J50-J41)*3.5% -> 977.75375 | L41: % | O41: млн. руб. | P41: ='CF2'!E84 -> 142.20064 | R41: IRR ПРОЕКТА (pre-tax) | U41: =POWER((1+IRR('CF2'!F76:BM76,0.01)),4)-1 -> 0.18141414
B42: НЕПРЕДВИДЕННЫЕ РАСХОДЫ | F42: 0.02 | G42: % от расходов | H42: =IFERROR(J42/$G$18*1000000,0) -> 3903.5471 | I42: =IFERROR(J42/$H$18*1000000,0) -> 6169.3364 | J42: =SUM($J$31:$J$40)*$F42 -> 377.12167 | K42: =J41/(J43+J53-U36-J50-J41) -> 0.02753913 | L42: ПРОЦЕНТЫ | N42: =P42/$G$18*1000000 -> 39128.314 | O42: =P42/$H$18*1000000 -> 61840.097 | P42: =-U36 -> 3780.1862 | R42: IRR ИНВЕСТОРА | U42: =IFERROR(POWER((1+IRR('CF2'!F171:BM171,0.01)),4)-1,0) -> 0.68880863
B43: ИНВЕСТИЦИИ | H43: =IFERROR(J43/$G$18*1000000,0) -> 233913.89 | I43: =IFERROR(J43/$H$18*1000000,0) -> 369687.73 | J43: =SUM(J22,J24,J30) -> 22598.42 | R43: LLSR | U43: =(-U33-U37)/(U36-P33) -> 1.197184 | W43: 0.85
U44: ='DB1'!U43 -> 1.1962353
...

Sheet CF
B2: CF проекта
B4: 1 оч | F4: ='CF1'!F4 | G4: ='CF1'!G4 | H4: ='CF1'!H4 | I4: ='CF1'!I4 | J4: ='CF1'!J4 | K4: ='CF1'!K4 | L4: ='CF1'!L4 | M4: ='CF1'!M4 | ... BM4: ='CF1'!BM4 -> 0
B5: 2 оч | F5: ='CF2'!F3 | G5: ='CF2'!G3 | H5: ='CF2'!H3 | I5: ='CF2'!I3 | J5: ='CF2'!J3 | K5: ='CF2'!K3 | L5: ='CF2'!L3 | M5: ='CF2'!M3 | ... BM5: ='CF2'!BM3
B6: СТАТЬЯ | E6: ВСЕГО | F6: =EOMONTH('DB1'!$U$22,2) -> 45107 | G6: =EOMONTH(F6,3) -> 45199 | H6: =EOMONTH(G6,3) -> 45291 | I6: =EOMONTH(H6,3) -> 45382 | J6: =EOMONTH(I6,3) -> 45473 | K6: =EOMONTH(J6,3) -> 45565 | L6: =EOMONTH(K6,3) -> 45657 | M6: =EOMONTH(L6,3) -> 45747 | N6: =EOMONTH(M6,3) -> 45838 | ... BM6: =EOMONTH(BL6,3) -> 50495
F7: =CONCATENATE(IF(MONTH(F6)<=3,"1",IF(MONTH(F6)<=6,"2",IF(MONTH(F6)<=9,"3","4"))),"Q",YEAR(F6)) -> 2Q2023 | G7: =CONCATENATE(IF(MONTH(G6)<=3,"1",IF(MONTH(G6)<=6,"2",IF(MONTH(G6)<=9,"3","4"))),"Q",YEAR(G6)) -> 3Q2023 | H7: =CONCATENATE(IF(MONTH(H6)<=3,"1",IF(MONTH(H6)<=6,"2",IF(MONTH(H6)<=9,"3","4"))),"Q",YEAR(H6)) -> 4Q2023 | I7: =CONCATENATE(IF(MONTH(I6)<=3,"1",IF(MONTH(I6)<=6,"2",IF(MONTH(I6)<=9,"3","4"))),"Q",YEAR(I6)) -> 1Q2024 | J7: =CONCATENATE(IF(MONTH(J6)<=3,"1",IF(MONTH(J6)<=6,"2",IF(MONTH(J6)<=9,"3","4"))),"Q",YEAR(J6)) -> 2Q2024 | K7: =CONCATENATE(IF(MONTH(K6)<=3,"1",IF(MONTH(K6)<=6,"2",IF(MONTH(K6)<=9,"3","4"))),"Q",YEAR(K6)) -> 3Q2024 | L7: =CONCATENATE(IF(MONTH(L6)<=3,"1",IF(MONTH(L6)<=6,"2",IF(MONTH(L6)<=9,"3","4"))),"Q",YEAR(L6)) -> 4Q2024 | M7: =CONCATENATE(IF(MONTH(M6)<=3,"1",IF(MONTH(M6)<=6,"2",IF(MONTH(M6)<=9,"3","4"))),"Q",YEAR(M6)) -> 1Q2025 | ... BM7: =CONCATENATE(IF(MONTH(BM6)<=3,"1",IF(MONTH(BM6)<=6,"2",IF(MONTH(BM6)<=9,"3","4"))),"Q",YEAR(BM6)) -> 1Q2038
B8: КОНТРАКТАЦИЯ | D8: м2
B9: ='DB1'!B8 -> КВАРТИРЫ | D9: м2 | E9: =SUM(F9:BM9) -> 110302.71 | F9: =F10+F11 -> 0 | G9: =G10+G11 -> 0 | H9: =H10+H11 -> 0 | I9: =I10+I11 -> 0 | J9: =J10+J11 -> 0 | K9: =K10+K11 -> 0 | L9: =L10+L11 -> 0 | M9: =M10+M11 -> 0 | ... BM9: =BM10+BM11 -> 0
C10: 1 оч | D10: м2 | E10: =SUM(F10:BM10) -> 59425.363 | F10: ='CF1'!F8 -> 0 | G10: ='CF1'!G8 -> 0 | H10: ='CF1'!H8 -> 0 | I10: ='CF1'!I8 -> 0 | J10: ='CF1'!J8 -> 0 | K10: ='CF1'!K8 -> 0 | L10: ='CF1'!L8 -> 0 | M10: ='CF1'!M8 -> 0 | ... BM10: ='CF1'!BM8 -> 0
C11: 2 оч | D11: м2 | E11: =SUM(F11:BM11) -> 50877.343 | F11: ='CF2'!F8 -> 0 | G11: ='CF2'!G8 -> 0 | H11: ='CF2'!H8 -> 0 | I11: ='CF2'!I8 -> 0 | J11: ='CF2'!J8 -> 0 | K11: ='CF2'!K8 -> 0 | L11: ='CF2'!L8 -> 0 | M11: ='CF2'!M8 -> 0 | ... BM11: ='CF2'!BM8 -> 0
B12: ='DB1'!B9 -> АПАРТАМЕНТЫ | D12: м2 | E12: =SUM(F12:BM12) -> 0 | V12: ='CF2'!V9 -> 0
B13: ='DB1'!B10 -> ОФИСЫ | D13: м2 | E13: =SUM(F13:BM13) -> 0 | V13: ='CF2'!V10 -> 0
B14: ='DB1'!B11 -> РИТЕЙЛ | D14: м2 | E14: =SUM(F14:BM14) -> 6073.4115 | F14: =F15+F16 -> 0 | G14: =G15+G16 -> 0 | H14: =H15+H16 -> 0 | I14: =I15+I16 -> 0 | J14: =J15+J16 -> 0 | K14: =K15+K16 -> 0 | L14: =L15+L16 -> 0 | M14: =M15+M16 -> 0 | ... BM14: =BM15+BM16 -> 0
C15: 1 оч | D15: м2 | E15: =SUM(F15:BM15) -> 3517.353 | F15: ='CF1'!F11 -> 0 | G15: ='CF1'!G11 -> 0 | H15: ='CF1'!H11 -> 0 | I15: ='CF1'!I11 -> 0 | J15: ='CF1'!J11 -> 0 | K15: ='CF1'!K11 -> 0 | L15: ='CF1'!L11 -> 0 | M15: ='CF1'!M11 -> 0 | ... BM15: ='CF1'!BM11 -> 0
C16: 2 оч | D16: м2 | E16: =SUM(F16:BM16) -> 2556.0585 | F16: ='CF2'!F11 -> 0 | G16: ='CF2'!G11 -> 0 | H16: ='CF2'!H11 -> 0 | I16: ='CF2'!I11 -> 0 | J16: ='CF2'!J11 -> 0 | K16: ='CF2'!K11 -> 0 | L16: ='CF2'!L11 -> 0 | M16: ='CF2'!M11 -> 0 | ... BM16: ='CF2'!BM11 -> 0
B17: ='DB1'!B12 -> ТЦ | D17: м2 | E17: =SUM(F17:BM17) -> 0
B18: ='DB1'!B16 -> ПАРКИНГ ЖИЛЬЕ | D18: шт. | E18: =SUM(F18:BM18) -> 1112 | F18: =F19+F20 -> 0 | G18: =G19+G20 -> 0 | H18: =H19+H20 -> 0 | I18: =I19+I20 -> 0 | J18: =J19+J20 -> 0 | K18: =K19+K20 -> 0 | L18: =L19+L20 -> 0 | M18: =M19+M20 -> 0 | ... BM18: =BM19+BM20 -> 0
C19: 1 оч | D19: шт. | E19: =SUM(F19:BM19) -> 599 | F19: ='CF1'!F13 -> 0 | G19: ='CF1'!G13 -> 0 | H19: ='CF1'!H13 -> 0 | I19: ='CF1'!I13 -> 0 | J19: ='CF1'!J13 -> 0 | K19: ='CF1'!K13 -> 0 | L19: ='CF1'!L13 -> 0 | M19: ='CF1'!M13 -> 0 | ... BM19: ='CF1'!BM13 -> 0
C20: 2 оч | D20: шт. | E20: =SUM(F20:BM20) -> 513 | F20: ='CF2'!F13 -> 0 | G20: ='CF2'!G13 -> 0 | H20: ='CF2'!H13 -> 0 | I20: ='CF2'!I13 -> 0 | J20: ='CF2'!J13 -> 0 | K20: ='CF2'!K13 -> 0 | L20: ='CF2'!L13 -> 0 | M20: ='CF2'!M13 -> 0 | ... BM20: ='CF2'!BM13 -> 0
B21: ='DB1'!B17 -> ПАРКИНГ ОФИС | D21: шт. | E21: =SUM(F21:BM21) -> 0
B23: ЦЕНЫ | D23: тыс. руб. | E23: =IFERROR(E38/E8*1000,0) -> 0
B24: =B9 -> КВАРТИРЫ | D24: тыс. руб. | E24: =IFERROR(E39/E9*1000,0) -> 630 | F24: =IFERROR(F39/F9,0)*1000 -> 0 | G24: =IFERROR(G39/G9,0)*1000 -> 0 | H24: =IFERROR(H39/H9,0)*1000 -> 0 | I24: =IFERROR(I39/I9,0)*1000 -> 0 | J24: =IFERROR(J39/J9,0)*1000 -> 0 | K24: =IFERROR(K39/K9,0)*1000 -> 0 | L24: =IFERROR(L39/L9,0)*1000 -> 0 | M24: =IFERROR(M39/M9,0)*1000 -> 0 | ... BM24: =IFERROR(BM39/BM9,0)*1000 -> 0
C25: 1 оч | D25: тыс. руб. | E25: =IFERROR(E40/E10*1000,0) -> 630 | F25: ='CF1'!F17 -> 0 | G25: ='CF1'!G17 -> 0 | H25: ='CF1'!H17 -> 0 | I25: ='CF1'!I17 -> 0 | J25: ='CF1'!J17 -> 0 | K25: ='CF1'!K17 -> 0 | L25: ='CF1'!L17 -> 0 | M25: ='CF1'!M17 -> 0 | ... BM25: ='CF1'!BM17 -> 0
C26: 2 оч | D26: тыс. руб. | E26: =IFERROR(E41/E11*1000,0) -> 630 | F26: ='CF2'!F17 -> 0 | G26: ='CF2'!G17 -> 0 | H26: ='CF2'!H17 -> 0 | I26: ='CF2'!I17 -> 0 | J26: ='CF2'!J17 -> 0 | K26: ='CF2'!K17 -> 0 | L26: ='CF2'!L17 -> 0 | M26: ='CF2'!M17 -> 0 | ... BM26: ='CF2'!BM17 -> 0
B27: =B12 -> АПАРТАМЕНТЫ | D27: тыс. руб. | E27: =IFERROR(E42/E12*1000,0) -> 0
B28: =B13 -> ОФИСЫ | D28: тыс. руб. | E28: =IFERROR(E43/E13*1000,0) -> 0
B29: =B14 -> РИТЕЙЛ | D29: тыс. руб. | E29: =IFERROR(E44/E14*1000,0) -> 700 | F29: =IFERROR(F44/F14,0)*1000 -> 0 | G29: =IFERROR(G44/G14,0)*1000 -> 0 | H29: =IFERROR(H44/H14,0)*1000 -> 0 | I29: =IFERROR(I44/I14,0)*1000 -> 0 | J29: =IFERROR(J44/J14,0)*1000 -> 0 | K29: =IFERROR(K44/K14,0)*1000 -> 0 | L29: =IFERROR(L44/L14,0)*1000 -> 0 | M29: =IFERROR(M44/M14,0)*1000 -> 0 | ... BM29: =IFERROR(BM44/BM14,0)*1000 -> 0
C30: 1 оч | D30: тыс. руб. | E30: =IFERROR(E45/E15*1000,0) -> 700 | F30: ='CF1'!F20 -> 0 | G30: ='CF1'!G20 -> 0 | H30: ='CF1'!H20 -> 0 | I30: ='CF1'!I20 -> 0 | J30: ='CF1'!J20 -> 0 | K30: ='CF1'!K20 -> 0 | L30: ='CF1'!L20 -> 0 | M30: ='CF1'!M20 -> 0 | ... BM30: ='CF1'!BM20 -> 0
C31: 2 оч | D31: тыс. руб. | E31: =IFERROR(E46/E16*1000,0) -> 700 | F31: ='CF2'!F20 -> 0 | G31: ='CF2'!G20 -> 0 | H31: ='CF2'!H20 -> 0 | I31: ='CF2'!I20 -> 0 | J31: ='CF2'!J20 -> 0 | K31: ='CF2'!K20 -> 0 | L31: ='CF2'!L20 -> 0 | M31: ='CF2'!M20 -> 0 | ... BM31: ='CF2'!BM20 -> 0
B32: =B17 -> ТЦ | D32: тыс. руб. | E32: =IFERROR(E47/E17*1000,0) -> 0
B33: =B18 -> ПАРКИНГ ЖИЛЬЕ | D33: тыс. руб. | E33: =IFERROR(E48/E18*1000,0) -> 4500 | F33: =IFERROR(F48/F18,0)*1000 -> 0 | G33: =IFERROR(G48/G18,0)*1000 -> 0 | H33: =IFERROR(H48/H18,0)*1000 -> 0 | I33: =IFERROR(I48/I18,0)*1000 -> 0 | J33: =IFERROR(J48/J18,0)*1000 -> 0 | K33: =IFERROR(K48/K18,0)*1000 -> 0 | L33: =IFERROR(L48/L18,0)*1000 -> 0 | M33: =IFERROR(M48/M18,0)*1000 -> 0 | ... BM33: =IFERROR(BM48/BM18,0)*1000 -> 0
C34: 1 оч | D34: тыс. руб. | E34: =IFERROR(E49/E19*1000,0) -> 4500 | F34: ='CF1'!F22 -> 0 | G34: ='CF1'!G22 -> 0 | H34: ='CF1'!H22 -> 0 | I34: ='CF1'!I22 -> 0 | J34: ='CF1'!J22 -> 0 | K34: ='CF1'!K22 -> 0 | L34: ='CF1'!L22 -> 0 | M34: ='CF1'!M22 -> 0 | ... BM34: ='CF1'!BM22 -> 0
C35: 2 оч | D35: тыс. руб. | E35: =IFERROR(E50/E20*1000,0) -> 4500 | F35: ='CF2'!F22 -> 0 | G35: ='CF2'!G22 -> 0 | H35: ='CF2'!H22 -> 0 | I35: ='CF2'!I22 -> 0 | J35: ='CF2'!J22 -> 0 | K35: ='CF2'!K22 -> 0 | L35: ='CF2'!L22 -> 0 | M35: ='CF2'!M22 -> 0 | ... BM35: ='CF2'!BM22 -> 0
B36: =B21 -> ПАРКИНГ ОФИС | D36: тыс. руб. | E36: =IFERROR(E51/E21*1000,0) -> 0
B38: КОНТРАКТАЦИЯ | D38: млн. руб. | E38: =SUM(F38:BM38) -> 78746.093 | F38: =SUM(F39,F44,F48) -> 0 | G38: =SUM(G39,G44,G48) -> 0 | H38: =SUM(H39,H44,H48) -> 0 | I38: =SUM(I39,I44,I48) -> 0 | J38: =SUM(J39,J44,J48) -> 0 | K38: =SUM(K39,K44,K48) -> 0 | L38: =SUM(L39,L44,L48) -> 0 | M38: =SUM(M39,M44,M48) -> 0 | ... BM38: =SUM(BM39,BM44,BM48) -> 0
B39: =B24 -> КВАРТИРЫ | D39: млн. руб. | E39: =SUM(F39:BM39) -> 69490.705 | F39: =F40+F41 -> 0 | G39: =G40+G41 -> 0 | H39: =H40+H41 -> 0 | I39: =I40+I41 -> 0 | J39: =J40+J41 -> 0 | K39: =K40+K41 -> 0 | L39: =L40+L41 -> 0 | M39: =M40+M41 -> 0 | ... BM39: =BM40+BM41 -> 0
C40: 1 оч | D40: млн. руб. | E40: =SUM(F40:BM40) -> 37437.979 | F40: ='CF1'!F26 -> 0 | G40: ='CF1'!G26 -> 0 | H40: ='CF1'!H26 -> 0 | I40: ='CF1'!I26 -> 0 | J40: ='CF1'!J26 -> 0 | K40: ='CF1'!K26 -> 0 | L40: ='CF1'!L26 -> 0 | M40: ='CF1'!M26 -> 0 | ... BM40: ='CF1'!BM26 -> 0
C41: 2 оч | D41: млн. руб. | E41: =SUM(F41:BM41) -> 32052.726 | F41: ='CF2'!F26 -> 0 | G41: ='CF2'!G26 -> 0 | H41: ='CF2'!H26 -> 0 | I41: ='CF2'!I26 -> 0 | J41: ='CF2'!J26 -> 0 | K41: ='CF2'!K26 -> 0 | L41: ='CF2'!L26 -> 0 | M41: ='CF2'!M26 -> 0 | ... BM41: ='CF2'!BM26 -> 0
B42: =B27 -> АПАРТАМЕНТЫ | D42: млн. руб. | E42: =SUM(F42:BM42) -> 0 | F42: =F12*F27/10^3 -> 0 | G42: =G12*G27/10^3 -> 0 | H42: =H12*H27/10^3 -> 0 | I42: =I12*I27/10^3 -> 0 | J42: =J12*J27/10^3 -> 0 | K42: =K12*K27/10^3 -> 0 | L42: =L12*L27/10^3 -> 0 | M42: =M12*M27/10^3 -> 0 | ... BM42: =BM12*BM27/10^3 -> 0
B43: =B28 -> ОФИСЫ | D43: млн. руб. | E43: =SUM(F43:BM43) -> 0 | F43: =F13*F28/10^3 -> 0 | G43: =G13*G28/10^3 -> 0 | H43: =H13*H28/10^3 -> 0 | I43: =I13*I28/10^3 -> 0 | J43: =J13*J28/10^3 -> 0 | K43: =K13*K28/10^3 -> 0 | L43: =L13*L28/10^3 -> 0 | M43: =M13*M28/10^3 -> 0 | ... BM43: =BM13*BM28/10^3 -> 0
B44: =B29 -> РИТЕЙЛ | D44: млн. руб. | E44: =SUM(F44:BM44) -> 4251.388 | F44: =F45+F46 -> 0 | G44: =G45+G46 -> 0 | H44: =H45+H46 -> 0 | I44: =I45+I46 -> 0 | J44: =J45+J46 -> 0 | K44: =K45+K46 -> 0 | L44: =L45+L46 -> 0 | M44: =M45+M46 -> 0 | ... BM44: =BM45+BM46 -> 0
...

Sheet CF1
B2: CF проекта | C2: ОЧЕРЕДЬ | D2: 1
