Workbook

Sheet Тек
A3: 1 | B3: Доклад начальная встреча | N3: Скоуп
B4: 0. | C4: Тек статус - старт, целевой скоуп работ -> | N4: Список показателей ФМ (пример Мира) | R4: +методика сбора данных (РУКИ в основном:))
B5: 1. | C5: Список форм - драфт | N5: Список контролей ИИ | R5: + источники методика и приоритеты реализации
B6: 2. | C6: Логика набора показателей | N6: Формат\макет ввода загрузки - ФМ
B7: 3. | C7: Детализация расходов мин | N7: Формат\макет ввода загрузки - параметры проекта финка\ставки\эскроу для моделирования и сценарки
N8: Формат\макет ввода загрузки - цены рынка
N9: Формат ДЭШ
B10: Открытые вопросы | N10: ИТ логика (версионность, схема потоков)
B11: 1 | C11: Запрос текущих дешбоардов (для анализ требований к данным, описания методики\формул расчета, генерации новых отчетов)
B12: 2 | C12: Структура данных Кулешова (для анализа сопоставимости данных и описания хранения и загрузки)
B13: 3 | C13: Структура данных БИМ (можно след этапом не сейчас)
A20: 2 | B20: Вопрос отчетности по Юр лицам
A23: 3 | B23: ИТ и дизайн - уточнить подходы и планы?
B24: 0. | C24: Структура опер показателей для работы ИТ
B25: Далее
B26: 1. | C26: Структура фин показателей и расписывание логики блоков расчетов\ + спроектировать фин набор отчетности для учета в ФМ сразу
B27: 2. | C27: Необходим CJM + дизайн
B28: 3. | C28: Выбор стека ИТ и старт ИТ разработки (притирка постановки задач и сопровождения и сдачи результатов)
A32: 4 | B32: ЛЕГЕНДА ЯЧЕЕК
B33: НАЗВАНИЕ СТОЛБЦА | C33: ИТ в работу - описаны столбцы, формулы и тп - 1й ЭТАП
B35: 05-04 | C35: ввод пользователя
C37: согласовать\проговорить
B39: 0. Ручной +… | C39: Допишется потом
C41: ЛИСТ ДЛЯ РАБОТЫ МЕТОДОЛОГИИ - дальнейшие шаги

Sheet Этапы
B2: Рабочее понимание спринтов (2-3 недель) ДРАФТ | D2: версия ОПТИМИСТ | I2: Комментарий | J2: нояб | K2: дек | L2: янв | M2: февр | N2: март | O2: апрель | P2: май | Q2: июнь
B4: Этап 01 | C4: Согласовать базовый интерфейс модели, аналитики, базовая ИТ техника (хранения данных) | D4: Базовые статьи и аналитики - утв | J4: опер | K4: фин
D5: Структура данных для хранения и ввода (режим Dash) | J5: опер | K5: фин
D6: Дизайн система и схема экранов | K6: схема и мокап | L6: design front MVP
D7: Просмотр и ввод данных по периодам | L7: опер | M7: фин
D8: Просмотр и ввод факта ручную пока | L8: опер | M8: фин
B10: Этап 1 | C10: "Ручное" моделирование\ввод = ввод всех моделей по проектам | D10: Библиотеки - Механика пересчета опер и инвест статей - линейно\эпюры
D11: Библиотеки - Механика пересчета (налоги, ври, % и тп)
D12: Формирование ЧПД и тп
D13: ИТ реализация и тестирование | M13: ИТ | N13: ИТ | O13: ИТ +тест
B15: Этап 2 | C15: Перенос данных проектов и запуск ИИ | D15: Версионность сохранения
D16: Ролевая модель | K16: метод | M16: ИТ | N16: ИТ
D17: Ввод моделей по всем проектам
D18: ИИ контроль + метод и источники для сверки | N18: метод
D19: ИИ по проекту (контроль ввода, поиск информации, сравнение) | N19: ИТ | O19: ИТ +тест
B21: Этап 3 | C21: ИИ по проекту и дешбоарды\отчетность, в т.ч. между моделями | D21: Дешбоарды по проекту и портфелю | M21: метод | N21: ИТ
D22: Сценарное моделирование и сравнительный анализ (серийный) и расширенный ИИ | N22: метод | O22: ИТ | P22: ИТ +тест
D23: ИИ ассистент по порфтелю (интерактив) | O23: ИТ | P23: ИТ +тест
B25: Этап 4 | C25: Внешняя интеграция | D25: Методика загрузка факта и плана | O25: метод | P25: метод
B26: Космос | D26: Интеграция с источниками данных, факта и тп | O26: ИТ | P26: ИТ | Q26: ИТ +тест
D27: Фантазии

Sheet ИТ арх
C2: ЛОГИЧЕСКИЕ БЛОКИ
G4: ОТЧЕТНОСТЬ | I4: Контроли ИИ | L4: Интеграция онлайн ИИ ассистент
G8: Dashboard | H8: = | I8: Формы ввода | L8: Сценарное моделирование
C10: Общие справочники
G11: Методика план и учета (аллокации,распред расходов по проекту) | I11: Библиотеки - Модули калькуляции (доп расчеты при изм данных Налоги, ЗУ, Продажи, и тп)
E13: Справочники проекта+матрицы | H13: Хранение данных (показатели и методика расчетов)
C15: Общие настройки и права\роли
H16: Накопит ведомость\методика\аналитика + Интеграция
G18: Методика сбора факта + факт (шлюзы) или формы распрделения* | I18: Меппинг - + план (шлюз\импорт)
C21: ТЕКУЩИЕ ПРИОРИТЕТЫ
G22: ОТЧЕТНОСТЬ | I22: Контроли ИИ | L22: Интеграция онлайн ИИ ассистент
G26: Dashboard | H26: = | I26: Формы ввода | L26: Сценарное моделирование
C28: Общие справочники
G29: Методика план и учета (аллокации,распред расходов по проекту) | I29: Библиотеки - Модули калькуляции (доп расчеты при изм данных Налоги, ЗУ, Продажи, и тп)
E31: Справочники проекта+матрицы | H31: Хранение данных (показатели и методика расчетов)
C33: Общие настройки и права\роли
H34: Накопит ведомость\методика\аналитика + Интеграция
G35: Методика сбора факта + факт (шлюзы) или формы распрделения* | I35: Меппинг - + план (шлюз\импорт)
C40: Детализация факта
C43: * детал - банковская платежка 1С БИТ
C44: Статья | D44: Сумма | E44: Период | F44: ПК | G44: Период | H44: Проект | I44: Статья оборотов | J44: Организация | K44: Контрагент | L44: Договор контрагента | M44: Код договора | N44: Банковский счет | O44: Валюта | P44: Курс | Q44: НазначениеПлатежа | R44: Регистратор | S44: Приход в валюте | T44: Расход в валюте | U44: Приход в рублях | V44: Расход в рублях
C48: Вомозможен меппинг на работу (ане комбинацию Контрганет Договор

Sheet Структура
B2: РАЗДЕЛЫ ИТ решения по ФМ
B4: 1 | C4: СПИСОК ФМ | G4: Навигая по списку ФМ с учетом версионности
C5: ИИ Сводный анализ портфеля | G5: Общая аналитика проектов: ключевые показатели и алармы в тч с помощб. ИИ
B7: 2 | C7: СВОД ПО ФМ | G7: Краткое резюме ФМ проекта и последних изменений | H7: ТИПА РАЗВОРАЧИВАЕТСЯ НА ВЕСЬ ЭКРАН ДЛЯ ВВОДА
B8: 3 | C8: DASH BBOДА или-> | D8: ФОРМЫ ВВОДА ФМ | G8: Последовательные формы для ввода и\или загрузки данных с ИИ контролем ввода. Также могут функционировать в режим просмотра ранее загруженных данных (режим просмотра)
D9: 1 | E9: ТЭП
D10: 2 | E10: Продажи
D11: 3 | E11: Расходы
D12: 4 | E12: см - далее
D14: 99 | E14: ДОП формы | G14: Формы для загрузки доп данных для сверки, контроля и проверок ИИ
B15: 4 | C15: ИИ АНАЛИЗ ФМ | G15: СВОДНАЯ: ИИ контроль ввода данных, тройная проверка, ИИ рекомендации и анализ по ФМ в целом + заключение ИИ, интекрактив ИИ
B16: 5 | C16: ОТЧЕТЫ
B18: 6 | C18: СРАВНИТЕЛЬНЫЙ АНАЛИЗ \ МОДЕЛИРОВАНИЕ ФМ
B20: 7 | C20: ЖУРНАЛ\РОЛИ
B26: Схема основных экранов
C28: MAIN | E28: ИИ Сводный анализ портфеля
E30: СПИСОК ФМ | G30: ИИ АНАЛИЗ ФМ
G32: DASH
G34: Схема FM (СМ ЛИСТ СХЕМА)
G35: Ф0
G36: Ф0БК
G37: Ф1
G38: …
E39: Reports
E41: ….
E44: ЖУРНАЛ\РОЛИ
C49: Ближайщие задачи!
C50: Цветовая гамма - темная (постельная коричневый) и светлая (синия, бирюзовая, белая) - можно набор пока скришотов разных программ с цветовым стилем
C51: Изменения - цвет и спобосы индикации (шрифт цвет, иконки и тп): изменилось +-, превышение лимита, ошибка, комментарий
C52: Макеты Dash Main
C54: Пятница 11-30

Sheet Диз_Ф1
B1: Эскиз макета дизайна - набор аналитик | R1: ТИПА СДЕЛАТЬ ДВА РЕЖИМА / СЧЖАТЫЙ И РАСЩШИРЕННЫЙ по столбцам!!! Например не только часть тослбцов скрывать но и по месяцам, а часть столбцов данных и комментариев - выводить в боковой панели
I2: наверно можно выводить в подсказке всп при наведении на ИТОГО норматив, т.к. надо не тольк осам норматив его значение еще есть столбец ед изм например и тп | P2: можно обсуждать | S2: либо выводить инконку разныую в зависимости от критичности замечания ИИ, а сам текст комментария уже при наведении
C4: 01 | D4: Продажи\контрактация
AA5: переключатель: месяц\квартал \ год
D6: КОД | E6: Показатель | F6: Код | G6: Аналитика | H6: ед изм | I6: Норматив | J6: Расценка | K6: ИТОГО норматив | L6: ИТОГО пред | M6: ИТОГО | N6: изм абс\% | O6: Отклонение абс\% | P6: Пересчет (кнопки\иконки | Q6: Описание | R6: Комментарий | S6: Комментарий ИИ | T6: ИТОГО за период | U6: 45658 | V6: 45689 | W6: 45717 | X6: 45748 | Y6: 45778 | Z6: 45809 | AA6: 45839 | AB6: ….
D7: 01-01 | E7: Обьем продаж | H7: руб\м2 | I7: 24 | J7: 10 | K7: 240 | L7: 200 | M7: 300 | N7: =M7/L7-1 -> 0.5 | O7: =M7-T7 -> 20 | P7: иконки ОШИБКА/ПЕРЕСЧЕТ \ ПОКАЗАТЬ ГРАФИК / СКАЧАТЬ (но может быть разнести их по строке гдето или в конец) | Q7: текст тексттекст тексттекст тексттекст тексттекст тексттекст текст | R7: ввод пользователя текст | S7: текст тексттекст тексттекст тексттекст тексттекст тексттекст текст | T7: =SUM(U7:AA7) -> 280 | U7: 10 | V7: 20 | W7: 30 | X7: 40 | Y7: 50 | Z7: 60 | AA7: 70 | AB7: …
F8: 01 | G8: Жилье | H8: руб\м2 | I8: 34 | J8: 34 | L8: 200 | M8: 300 | N8: =M8-L8 -> 100 | O8: =M8-T8 -> 160 | P8: иконки (но может быть разнести | Q8: текст тексттекст тексттекст тексттекст тексттекст тексттекст текст | S8: текст тексттекст тексттекст тексттекст тексттекст тексттекст текст | T8: =SUM(U8:AA8) -> 140 | U8: 5 | V8: 10 | W8: 15 | X8: 20 | Y8: 25 | Z8: 30 | AA8: 35 | AB8: … | AF8: продажам - есть показатель и уточняющая показатель аналитика. надо продумать как выводить если есть иерархия показателя
F9: 01-01 | G9: MR Base | H9: руб\м2 | I9: 4 | J9: 343 | L9: 200 | M9: 300 | N9: =M9-L9 -> 100 | O9: =M9-T9 -> 160 | P9: иконки (но может быть разнести | Q9: текст тексттекст тексттекст тексттекст тексттекст тексттекст текст | S9: текст тексттекст тексттекст тексттекст тексттекст тексттекст текст | T9: =SUM(U9:AA9) -> 140 | U9: 5 | V9: 10 | W9: 15 | X9: 20 | Y9: 25 | Z9: 30 | AA9: 35 | AB9: … | AF9: 2. Думаю сохранить можно оставить только на всей форме (пока можно и так оставить)
F10: … | H10: руб\м2 | I10: 3 | J10: 2 | L10: 200 | M10: 300 | N10: =M10-L10 -> 100 | O10: =M10-T10 -> 300 | P10: иконки (но может быть разнести | Q10: текст тексттекст тексттекст тексттекст тексттекст тексттекст текст | S10: текст тексттекст тексттекст тексттекст тексттекст тексттекст текст | AB10: … | AF10: 3. Мы говорили что у каждого показателя есть - значение, скорректированное значение, метод расчета и кнопка для вызова расчета , чтобы пересчитать.... ну может поле описание еще добавить (или его по значку вопроса показывать)
D11: 01-02 | E11: Цена продаж | H11: м2 | I11: 24 | J11: 10 | K11: 240 | L11: 200 | M11: 300 | N11: =M11/L11-1 -> 0.5 | O11: =M11-T11 -> 20 | P11: иконки ПЕРЕСЧЕТ \ ПОКАЗАТЬ ГРАФИК / СКАЧАТЬ (но может быть разнести их по строке гдето или в конец) | S11: текст тексттекст тексттекст тексттекст тексттекст тексттекст текст | T11: =SUM(U11:AA11) -> 280 | U11: 10 | V11: 20 | W11: 30 | X11: 40 | Y11: 50 | Z11: 60 | AA11: 70 | AB11: … | AF11: Счас обсуждали ещё может быть значение драйвера и удельное значение.
F12: 01 | G12: Жилье | I12: 34 | J12: 34 | L12: 200 | M12: 300 | N12: =M12-L12 -> 100 | O12: =M12-T12 -> 160 | P12: иконки (но может быть разнести | S12: текст тексттекст тексттекст тексттекст тексттекст тексттекст текст | T12: =SUM(U12:AA12) -> 140 | U12: 5 | V12: 10 | W12: 15 | X12: 20 | Y12: 25 | Z12: 30 | AA12: 35 | AB12: … | AF12: Например. СТРОЙКА ДОМА - итого было 700 руб, итого стало 800 руб, всего м2 - 50 (драйвер) , сред значение - 160. ДАЛЕЕ КНОПКА ДИАЛОГА и текущий метод расчёта значений по месяцам (например линейо).
F13: 01-01 | G13: MR Base | I13: 4 | J13: 343 | L13: 200 | M13: 300 | N13: =M13-L13 -> 100 | O13: =M13-T13 -> 160 | P13: иконки (но может быть разнести | S13: текст тексттекст тексттекст тексттекст тексттекст тексттекст текст | T13: =SUM(U13:AA13) -> 140 | U13: 5 | V13: 10 | W13: 15 | X13: 20 | Y13: 25 | Z13: 30 | AA13: 35 | AB13: …
F14: … | I14: 3 | J14: 2 | L14: 200 | M14: 300 | N14: =M14-L14 -> 100 | O14: =M14-T14 -> 300 | P14: иконки (но может быть разнести | S14: текст тексттекст тексттекст тексттекст тексттекст тексттекст текст | AB14: …
D15: 01-04 | E15: Продажи выручка | G15: Вид ОН | H15: руб | I15: 24 | J15: 10 | K15: 240 | L15: 200 | M15: 300 | N15: =M15/L15-1 -> 0.5 | O15: =M15-T15 -> -78100 | P15: иконки ПЕРЕСЧЕТ \ ПОКАЗАТЬ ГРАФИК / СКАЧАТЬ (но может быть разнести их по строке гдето или в конец) | S15: текст тексттекст тексттекст тексттекст тексттекст тексттекст текст | T15: =T11*T7 -> 78400 | U15: =U11*U7 -> 100 | V15: =V11*V7 -> 400 | W15: =W11*W7 -> 900 | X15: =X11*X7 -> 1600 | Y15: =Y11*Y7 -> 2500 | Z15: =Z11*Z7 -> 3600 | AA15: =AA11*AA7 -> 4900 | AB15: …
F16: 01 | G16: Жилье | I16: 34 | J16: 34 | L16: 200 | M16: 300 | N16: =M16-L16 -> 100 | O16: =M16-T16 -> -19300 | P16: иконки (но может быть разнести | S16: текст тексттекст тексттекст тексттекст тексттекст тексттекст текст | T16: =T12*T8 -> 19600 | U16: =U12*U8 -> 25 | V16: =V12*V8 -> 100 | W16: =W12*W8 -> 225 | X16: =X12*X8 -> 400 | Y16: =Y12*Y8 -> 625 | Z16: =Z12*Z8 -> 900 | AA16: =AA12*AA8 -> 1225 | AB16: …
F17: 01-01 | G17: MR Base | I17: 4 | J17: 343 | L17: 200 | M17: 300 | N17: =M17-L17 -> 100 | O17: =M17-T17 -> -19300 | P17: иконки (но может быть разнести | S17: текст тексттекст тексттекст тексттекст тексттекст тексттекст текст | T17: =T13*T9 -> 19600 | U17: =U13*U9 -> 25 | V17: =V13*V9 -> 100 | W17: =W13*W9 -> 225 | X17: =X13*X9 -> 400 | Y17: =Y13*Y9 -> 625 | Z17: =Z13*Z9 -> 900 | AA17: =AA13*AA9 -> 1225 | AB17: …
F18: … | I18: 3 | J18: 2 | L18: 200 | M18: 300 | N18: =M18-L18 -> 100 | O18: =M18-T18 -> 300 | P18: иконки (но может быть разнести | S18: текст тексттекст тексттекст тексттекст тексттекст тексттекст текст | AB18: …
D19: 02-01 | E19: Поступления от реализации ОН | H19: руб | I19: 24 | J19: 10 | K19: 240 | L19: 200 | M19: 300 | N19: =M19/L19-1 -> 0.5 | O19: =M19-T19 -> -156500 | P19: иконки ПЕРЕСЧЕТ \ ПОКАЗАТЬ ГРАФИК / СКАЧАТЬ (но может быть разнести их по строке гдето или в конец) | S19: текст тексттекст тексттекст тексттекст тексттекст тексттекст текст | T19: =T15*2 -> 156800 | U19: =U15*2 -> 200 | V19: =V15*2 -> 800 | W19: =W15*2 -> 1800 | X19: =X15*2 -> 3200 | Y19: =Y15*2 -> 5000 | Z19: =Z15*2 -> 7200 | AA19: =AA15*2 -> 9800 | AB19: …
F20: 01 | G20: Жилье | I20: 34 | J20: 34 | L20: 200 | M20: 300 | N20: =M20-L20 -> 100 | O20: =M20-T20 -> -38900 | P20: иконки (но может быть разнести | S20: текст тексттекст тексттекст тексттекст тексттекст тексттекст текст | T20: =T16*2 -> 39200 | U20: =U16*2 -> 50 | V20: =V16*2 -> 200 | W20: =W16*2 -> 450 | X20: =X16*2 -> 800 | Y20: =Y16*2 -> 1250 | Z20: =Z16*2 -> 1800 | AA20: =AA16*2 -> 2450 | AB20: …
F21: 01-01 | G21: MR Base | I21: 4 | J21: 343 | L21: 200 | M21: 300 | N21: =M21-L21 -> 100 | O21: =M21-T21 -> -38900 | P21: иконки (но может быть разнести | S21: текст тексттекст тексттекст тексттекст тексттекст тексттекст текст | T21: =T17*2 -> 39200 | U21: =U17*2 -> 50 | V21: =V17*2 -> 200 | W21: =W17*2 -> 450 | X21: =X17*2 -> 800 | Y21: =Y17*2 -> 1250 | Z21: =Z17*2 -> 1800 | AA21: =AA17*2 -> 2450 | AB21: …
F22: … | I22: 3 | J22: 2 | L22: 200 | M22: 300 | N22: =M22-L22 -> 100 | O22: =M22-T22 -> 300 | P22: иконки (но может быть разнести | S22: текст тексттекст тексттекст тексттекст тексттекст тексттекст текст | AB22: …
D23: 02-02 | E23: Прочие опер поступления | H23: руб | I23: 24 | J23: 10 | K23: 240 | L23: 200 | M23: 300 | N23: =M23/L23-1 -> 0.5 | O23: =M23-T23 -> -313300 | P23: иконки ПЕРЕСЧЕТ \ ПОКАЗАТЬ ГРАФИК / СКАЧАТЬ (но может быть разнести их по строке гдето или в конец) | S23: текст тексттекст тексттекст тексттекст тексттекст тексттекст текст | T23: =T19*2 -> 313600 | U23: =U19*2 -> 400 | V23: =V19*2 -> 1600 | W23: =W19*2 -> 3600 | X23: =X19*2 -> 6400 | Y23: =Y19*2 -> 10000 | Z23: =Z19*2 -> 14400 | AA23: =AA19*2 -> 19600 | AB23: …
D24: 02-03 | E24: Поступления по аренде | H24: руб | I24: 24 | J24: 10 | K24: 240 | L24: 200 | M24: 300 | N24: =M24/L24-1 -> 0.5 | O24: =M24-T24 -> -78100 | P24: иконки ПЕРЕСЧЕТ \ ПОКАЗАТЬ ГРАФИК / СКАЧАТЬ (но может быть разнести их по строке гдето или в конец) | S24: текст тексттекст тексттекст тексттекст тексттекст тексттекст текст | T24: =T20*2 -> 78400 | U24: =U20*2 -> 100 | V24: =V20*2 -> 400 | W24: =W20*2 -> 900 | X24: =X20*2 -> 1600 | Y24: =Y20*2 -> 2500 | Z24: =Z20*2 -> 3600 | AA24: =AA20*2 -> 4900 | AB24: …
D25: 02-04 | E25: Поступления по услугам эксплуатации | H25: руб | I25: 4 | J25: 10 | K25: 240 | L25: 200 | M25: 300 | N25: =M25/L25-1 -> 0.5 | O25: =M25-T25 -> -78100 | P25: иконки ПЕРЕСЧЕТ \ ПОКАЗАТЬ ГРАФИК / СКАЧАТЬ (но может быть разнести их по строке гдето или в конец) | S25: текст тексттекст тексттекст тексттекст тексттекст тексттекст текст | T25: =T21*2 -> 78400 | U25: =U21*2 -> 100 | V25: =V21*2 -> 400 | W25: =W21*2 -> 900 | X25: =X21*2 -> 1600 | Y25: =Y21*2 -> 2500 | Z25: =Z21*2 -> 3600 | AA25: =AA21*2 -> 4900 | AB25: …

Sheet Поток
L1: Библиотеки - Модули калькуляции
H4: ПРОДАЖИ
H9: ПОСТУПЛЕНИЯ
H10: НАЗЕМНАЯ ЧАСТЬ | L10: Расчет динамики цен
H11: ПОДЗЕМНАЯ ЧАСТЬ | L11: Расчет динамики обьема продаж
B22: Сроки | L22: ДОПОЛНИТЕЛЬНЫЙ ВЫКУП ЗУ
B23: Дата РНС
B24: Дата РНВ | L24: ЗУ
B25: Дата СМР | H25: ИНВЕСТИЦИИ | L25: ВИД ПРАВА
B26: Дата ИРД | H26: ВХОД | L26: АРЕНДА / НАЛОГ ЗУ после ввода
B27: Дата продажи | H27: ЗЕМЕЛЬНО-ПРАВОВЫЕ ВОПРОСЫ | L27: ПЛОЩАДЬ ЗУ
E28: ТЭП | H28: ВЛОЖЕНИЯ В СТРОИТЕЛЬСТВО | L28: УДЕЛЬНАЯ ТЕКУЩАЯ КС
E29: НАЗЕМНАЯ ЧАСТЬ
E30: ПОДЗЕМНАЯ ЧАСТЬ | L30: ПРОЕКТИРОВАНИЕ (К+П+РД)
L31: СОГЛАСОВАНИЯ
L32: СМР жилье
L33: СМР офисы
L34: СМР ТЦ
L35: СМР соц. объектов и компенсация
L36: УСТРОЙСТВО УДС
L37: СЕТИ
L38: СОДЕРЖАНИЕ ПЛОЩАДКИ
L39: МОНИТОРИНГИ
L40: НЕПРЕДВИДЕННЫЕ РАСХОДЫ
L41: УПРАВЛЕНИЕ ПРОЕКТОМ
H48: РАСХОДЫ НА ПРОДАЖУ
H49: АХР | L49: АХР
H50: РЕКЛАМА И МАРКЕТИНГ | L50: РЕКЛАМА И МАРКЕТИНГ
H51: БРОКЕРИДЖ | L51: БРОКЕРИДЖ
H52: УПРАВЛЕНИЕ ПРОДАЖАМИ | L52: УПРАВЛЕНИЕ ПРОДАЖАМИ
H53: РЕГИСТРАЦИЯ ДОГОВОРОВ | L53: РЕГИСТРАЦИЯ ДОГОВОРОВ
H54: АРЕНДА / НАЛОГ ЗУ
L56: Налоги
L57: НДС
L58: НАЛОГ НА ПРИБЫЛЬ
L59: НАЛОГ НА ИМУЩЕСТВО
H62: ФИНАНСИРОВАНИЕ
L63: Эскроу
L64: Рассрочка
L65: Кредиты

Sheet Роли
B2: Минимальная
B4: Чтение и редактирование
B6: Админ
B10: Целевая модель (требования) | C10: в идеале иметь возможность накладывать матрично
B12: Управление пользователями (назначение ролей и разрешений)
B14: Разграничение по проектам, в т.ч. внутри проекта
B16: Разграничение на чтение на уровне форм (достаточно)
B18: Разграничение на редактирование на уровне форм (идеально на уровне показателей)
B20: Разграничение - да\нет редактирование справочников и табли использования\соответствия по конкретному проекту (обьект строительства, матрица использования статей)
B22: Управление версиями моделей (восстановить, удалить\архивировать, скопировать, сделать базовой)
B24: Управление импортом и экспортом данных
B26: Редактирование "глобальных" справочников (список проектов, общих статей и меппингов)
B28: Управление общими настройками и администрирование тп
B30: Управление общим импортом и экспортом данных
B32: Разграничение по разделам ИТ решения
B34: Суперадмин

Sheet Концепт
B1: Концепт (функ требования)
B3: Сценарий работы (общая логика и предназначение)
B5: Финансовые модели делаются по проектам 1-1.
B7: Ключевые измерения для ввода данных по модели: Форма\Статья\"Работа" - Проект\ПК\Урбанблок - Период\Бюджет(ИТОГО) - План\факт - Юрлица | G7: * еще измерение план-факт Контрагент\Договор( | L7: * еще измерение РАБОТА (ввод ручной) - кастомная детализация Статья
B8: Финасовая модель проекта вводится по статьям которые можно группировать по разделам (см формы) - Технические, финансовые и сроки.
B9: Детализация статей может быть
B10: а) | C10: иерархической
B11: б) | C11: детализроваться доп аналитикой\справочников (которые динамические в том числе
B13: Значение по статей может вводиться по проекту-очереди\пк - урбанблоку\строению. Это может меняться в ходе проекта(
B15: Значение в зависимости от статьи и типа может вводится итого либо в разбивке к периодам (значение ИТОГО может быть сумма значений периодов, может быть расчетным через другие показателей, либо суммой по иерархии аналитики\статей). Например, ИТОГО продажи, Средневзвешенная цена, Выручка по всем видам квартир
B17: Значения могут быть плановые и фактические, версия содержащая факт и перепланированный план до конца проекту - это прогноз
B20: Ключевая задача дать возможность выбирать комбинации аналитик, а также управлять ее - на уровне ввода.
B21: Открытый вопрос как отслеивать ее на разных уровнях во времение \ переразносить , а также еще синхронизировать в измерении план-факт
B22: Даже если всегда пересчитывать и дать возможномть задавать драйвера, надо показывать шде это первчиный факт и где распредленный.
B24: Требования к структуре данных
B26: Вопрос к ИТ
B27: Сильно напоминает SAP BI IP)
C37: Поступления
B38: Опер
C39: Выплаты
B41: Фин | C41: Банковские
C42: Финансирование
B44: ЧДП
B46: Участники

Sheet ПФ
B1: Формирование прогноза - пф
B4: Ключевой момент - по каждой статье етсь несолкько типов данных , при расчете занечения систаьи и контроле ввода данных используются суммыа ныжных типов данных по их видам. ТО ЕСТЬ ДАННЫЕ В РАЗРЕВЕ типов данных!!! В заисимости от того как эти данные получены\вносятся
A6: Тип | B6: Описание | C6: Вид данных
A7: расчетные | B7: плановые значения по статье полученные расчетным способом | C7: план
A8: корретировка | B8: плановые значения по статье внесенные вручную ("оттаскивание часть суммы" - например при заключении договора или явного пониманиия сумм и дат) | C8: план
A9: факт | B9: хранение факта по статье | C9: факт
B15: Есть драйвер ПРОДАЖИ для расчета итого по статье маркетинг | D15: ПРОДАЖИ | G15: 100 | H15: 200 | I15: 300 | J15: 400
B16: 1. Расчет ИТОГО по маркетингу солано нормативу - см ли Нормативы
B17: 2. Расрпдленеи ИТОГо во времени согласно алогритму - см | D17: Маркетинг | E17: 10% с продаж | F17: 100 | G17: 25 | H17: 25 | I17: 25 | J17: 25
D18: расчет план | F18: 100 | G18: 25 | H18: 25 | I18: 25 | J18: 25
G24: 1кв
D25: ПРОДАЖИ | G25: 100 | H25: 100 | I25: 100 | J25: 100
D27: Маркетинг | E27: 0.125 | F27: 100 | G27: =G28+G29 -> 37.5 | H27: =H28+H29 -> 37.5 | I27: =I28+I29 -> 12.5 | J27: =J28+J29 -> 12.5
D28: расчет план | F28: 50 | G28: 12.5 | H28: 12.5 | I28: 12.5 | J28: 12.5
B29: Руччной ввод коррекровки - заключен договор, необходомо чатсь расходов провести раньше или известные даты и конкрутные суммы | D29: корр | F29: 50 | G29: 25 | H29: 25
B30: Внесли 25 25 по
D31: факт
D34: ПРОДАЖИ | G34: 100 | H34: 100 | I34: 100 | J34: 100
D36: Маркетинг | E36: 0.125 | F36: 100 | G36: =G37+G38 -> 37.5 | H36: =H37+H38 -> 37.5 | I36: =I37+I38 -> 12.5 | J36: =J37+J38 -> 12.5
D37: расчет план | F37: 50 | G37: 12.5 | H37: 12.5 | I37: 12.5 | J37: 12.5
D38: корр | F38: 50 | G38: 25 | H38: 25
D40: факт | F40: 10 | G40: =7+3 -> 10
D43: ПРОДАЖИ | G43: 100 | H43: 100 | I43: 100 | J43: 100 | M43: 0.221
D45: Маркетинг | E45: 0.125 | F45: 100 | G45: =G46+G47+G49 -> 10 | H45: =H46+H47+H49 -> 47 | I45: =I46+I47+I49 -> 22 | J45: =J46+J47+J49 -> 22
D46: расчет план | F46: 66 | H46: 22 | I46: 22 | J46: 22 | M46: попасть в итого
D47: корр | F47: 25 | H47: 25
D49: факт | F49: 10 | G49: =7+3 -> 10
D53: ПРОДАЖИ | G53: 100 | H53: 100 | I53: 100 | J53: 100
D55: Маркетинг | E55: 0.125 | F55: 72.5 | G55: =G56+G57+G59 -> 10 | H55: =H56+H57+H59 -> 37.5 | I55: =I56+I57+I59 -> 12.5 | J55: =J56+J57+J59 -> 12.5 | M55: линейно - продолжае по нормативу
D56: расчет план | F56: 66 | H56: 12.5 | I56: 12.5 | J56: 12.5
D57: корр | F57: 25 | H57: 25
D59: факт | F59: 10 | G59: =7+3 -> 10
G68: 1кв
D69: ПРОДАЖИ | F69: 200 | G69: 100 | H69: 100
G70: 0.1 | H70: 0.1
D71: Брокеридж | E71: 0.1 | F71: 20 | G71: 10 | H71: 10
D72: расчет план | F72: 20 | G72: 10 | H72: 10
D73: корр
D77: ПРОДАЖИ | F77: 200 | G77: 50 | H77: 100 | I77: 50
D79: Брокеридж | E79: 0.1 | F79: 20 | G79: 10 | H79: 10 | L79: =I80/I77 -> 0.12
...

Sheet Схема
B1: Методика планирования модели - user case logic
B3: Схема работы создания модели
B5: I | C5: Создание модели
C6: Создание проекта | D6: Принятие решении о финасовом моделирование проекта и сбор первичной информации: название краткое\рабочее\коммерческое, отв-ный, срок, информация об участках, застройщик, адрес, описание
C7: Настройка справочников | D7: Настройка (создание) справочников для использование в проекте на основе типовых структур: Статей и ед изм, Проект-ПК-ОбСт, Периодичность: мес\квартал, Видов продаваемых ОН, Участков
C8: Настройка нормативов и расценок | D8: Настройка (на основе типовых) нормативов и расценок, % ставок, расчетов показателей (формул) если доступно для показателя
C9: Настройка распределения | D9: Выбор уровня ввода и логики расчетов показателей - по уровням измерений (агрегаций)
B11: II | C11: Формирование показателей
B12: 00 | C12: ТЭП
B13: 09 | C13: СРОКИ
B14: 01 | C14: Продажи\контрактация
B15: 02 | C15: Поступления
B16: 03 | C16: Коммерческие расходы
B17: 04 | C17: ЗУ и ИРД
B18: 05 | C18: Проектирование и СМР
B19: 06 | C19: АХР
B20: 07 | C20: Налоги
B21: 08 | C21: Финансы
C25: ОСНОВНЫЕ ПРИНЦИПЫ И ЛОГИКИ ПЕРЕСЧЕТОВ
C26: Общая логика планирования | F26: Общая логика ПЕРЕ планирования | J26: Общая логика прогноза (факт+план)
B27: 1 | C27: Ввод параметров и справочников
B28: 2 | C28: Ввод и расчеты ИТОГО | D28: Нормативы и формулы
B29: 3 | C29: Ввод и распределение во времени, если применимо | D29: через БК
B30: 4 | C30: Финансовые расчеты
B31: 5 | C31: Методы распределения при агрегации и отчетах
B32: 6
C35: Кейсы,
C36: поеняли ТЭП норматив, что произошло
C37: внес факт в продажи
C38: поменял ДАТу РНВ
C39: Поменял ставку норматива - на уаправ проектаом
C40: Разибл участки на два
C42: Появилось разбивка по ПК

Sheet ГПок
B2: ГРУППА ПОКАЗАТЕЛЕЙ
E3: * в будущем можно разделить по отв-м (видеть\вводить\согласовывать свои разделы)
B4: Блоки показателей | C4: Название | D4: Примечание | E4: Отв\Согл
B5: 00 | C5: ТЭП
B6: 01 | C6: Продажи\контрактация
B7: 02 | C7: Поступления
B8: 03 | C8: Коммерческие расходы
B9: 04 | C9: ЗУ и ИРД
B10: 05 | C10: Проектирование и СМР
B11: 06 | C11: АХР
B12: 07 | C12: Налоги
B13: 08 | C13: Финансы
B14: 09 | C14: СРОКИ
B16: 70 | C16: Параметры | D16: Данные для моделирования и расчетов
B17: 71 | C17: Плотность | D17: Ввод параметров, модель расчетов
B18: 72 | C18: ЗУ | D18: Ввод параметров, модель расчетов
B19: 73 | C19: Эскроу | D19: Ввод параметров, модель расчетов
B20: 74 | C20: Рассрочка | D20: Ввод параметров, модель расчетов
B21: 75 | C21: Кредиты | D21: Ввод параметров, модель расчетов
B22: 76 | C22: Налоги | D22: Ввод параметров, модель расчетов
B23: 77 | C23: Ковенанты | D23: Ввод параметров, модель расчетов
B24: 78
B25: 79
B26: 80 | C26: Драйверы

Sheet Показатели
C1: Список основных показателей (все вводные и ключевые для расчетов) + матрица применения аналитик (измерения хранения) | L1: ВОПРОС как вибвать и сохранять если вначале был ПРОЕКТ а потом вдруг ПК.. Иди делать всегда нулевой ПК который распрделяется всегда? И вносим по ПК | N1: Проект - ПК-УБ | R1: ИТОГО | S1: Период | T1: План-факт | U1: Юр лиц | V1: Инвестор
A2: № | B2: Блок | E2: Вид деятельности | G2: Показатель | I2: Аналитика | J2: изм | K2: детализация | L2: метод | M2: комент | N2: Проект | O2: ПК | P2: УБ | Q2: метод расчета при разных уровнях( | S2: месяц | W2: контроль ИИ (вохможно здесть общие, а на формах уже проверки ввода | X2: источник (опция)
A3: =B3&"-"&F3 -> 00-01 | B3: 00 | C3: =VLOOKUP(B3,ГПок!$B:$E,2,0) -> ТЭП | D3: 0 | E3: - | F3: 01 | G3: Площадь ЗУ | I3: Участки | J3: Га | K3: проект (пока без ОС) | L3: ввод\сумма при детализации | M3: Пока нет очередей не сможем сверять с РНС | O3: X | Q3: делать вирт | R3: x | T3: Ф | W3: 0. Ретро 1. Сверка с документом по ЗУ
B4: 00 | C4: =VLOOKUP(B4,ГПок!$B:$E,2,0) -> ТЭП | I4: Уч1
B5: 00 | C5: =VLOOKUP(B5,ГПок!$B:$E,2,0) -> ТЭП | I5: Уч2
B6: 00 | C6: =VLOOKUP(B6,ГПок!$B:$E,2,0) -> ТЭП | I6: …
A7: =B7&"-"&F7 -> 00-02 | B7: 00 | C7: =VLOOKUP(B7,ГПок!$B:$E,2,0) -> ТЭП | D7: 0 | E7: - | F7: 02 | G7: Плотность застройки | J7: м2\Га | K7: проект (пока без ОС) | L7: ввод\расчет | O7: X | W7: 0. Ретро 1. Сверка с документом 2. выгрузка БИМ 3. Бенчмаркинг МРГ\внешний
A8: =B8&"-"&F8 -> 00-03 | B8: 00 | C8: =VLOOKUP(B8,ГПок!$B:$E,2,0) -> ТЭП | D8: 0 | E8: - | F8: 03 | G8: ГНС ГПЗУ | J8: м2 | K8: проект (пока без ОС) | O8: X
A9: =B9&"-"&F9 -> 00-04 | B9: 00 | C9: =VLOOKUP(B9,ГПок!$B:$E,2,0) -> ТЭП | D9: 0 | E9: - | F9: 04 | G9: ГНС наземная площадь | I9: Вид ОН | J9: м2 | K9: проект (пока без ОС) | L9: расчет (обычно) | O9: X | R9: X
A10: =B10&"-"&F10 -> 00- | B10: 00 | C10: =VLOOKUP(B10,ГПок!$B:$E,2,0) -> ТЭП | D10: 0 | E10: - | H10: 01 | I10: Жилье | J10: м2 | K10: проект (пока без ОС) | R10: X
A11: =B11&"-"&F11 -> 00- | B11: 00 | C11: =VLOOKUP(B11,ГПок!$B:$E,2,0) -> ТЭП | D11: 0 | E11: - | H11: 01-01 | I11: MR Base | J11: м2 | K11: проект (пока без ОС) | R11: X
A12: =B12&"-"&F12 -> 00- | B12: 00 | C12: =VLOOKUP(B12,ГПок!$B:$E,2,0) -> ТЭП | D12: 0 | E12: - | H12: … | J12: м2 | K12: проект (пока без ОС) | R12: X
A13: =B13&"-"&F13 -> 00-05 | B13: 00 | C13: =VLOOKUP(B13,ГПок!$B:$E,2,0) -> ТЭП | D13: 0 | E13: - | F13: 05 | G13: ОБЩАЯ наземная площадь | I13: Вид ОН | J13: м2 | K13: проект (пока без ОС) | O13: X | R13: X
A14: =B14&"-"&F14 -> 00- | B14: 00 | C14: =VLOOKUP(B14,ГПок!$B:$E,2,0) -> ТЭП | D14: 0 | E14: - | H14: 01 | I14: Жилье | J14: м2 | K14: проект (пока без ОС) | L14: либо ввод\либо сумма | M14: пока без кол-ва квартир,в т.ч. обеспеченность не считаем | R14: X
A15: =B15&"-"&F15 -> 00- | B15: 00 | C15: =VLOOKUP(B15,ГПок!$B:$E,2,0) -> ТЭП | D15: 0 | E15: - | H15: 01-01 | I15: MR Base | J15: м2 | K15: проект (пока без ОС) | R15: X
A16: =B16&"-"&F16 -> 00- | B16: 00 | C16: =VLOOKUP(B16,ГПок!$B:$E,2,0) -> ТЭП | D16: 0 | E16: - | H16: 01-02 | I16: MR Ready | J16: м2 | K16: проект (пока без ОС) | R16: X
A17: =B17&"-"&F17 -> 00- | B17: 00 | C17: =VLOOKUP(B17,ГПок!$B:$E,2,0) -> ТЭП | D17: 0 | E17: - | H17: 01-03 | I17: без отделки | J17: м2 | K17: проект (пока без ОС) | R17: X
A18: =B18&"-"&F18 -> 00- | B18: 00 | C18: =VLOOKUP(B18,ГПок!$B:$E,2,0) -> ТЭП | D18: 0 | E18: - | H18: 02 | I18: ритейл | J18: м2 | K18: проект (пока без ОС) | M18: пока без кол-ва мест СОО и ДОО | R18: X
A19: =B19&"-"&F19 -> 00- | B19: 00 | C19: =VLOOKUP(B19,ГПок!$B:$E,2,0) -> ТЭП | D19: 0 | E19: - | H19: 03 | I19: ДОУ | J19: м2 | K19: проект (пока без ОС) | R19: X
A20: =B20&"-"&F20 -> 00- | B20: 00 | C20: =VLOOKUP(B20,ГПок!$B:$E,2,0) -> ТЭП | D20: 0 | E20: - | H20: 04 | I20: Офисы | J20: м2 | K20: проект (пока без ОС) | R20: X
A21: =B21&"-"&F21 -> 00- | B21: 00 | C21: =VLOOKUP(B21,ГПок!$B:$E,2,0) -> ТЭП | D21: 0 | E21: - | H21: 05 | I21: Коммерческие | J21: м2 | K21: проект (пока без ОС) | L21: либо ввод\либо сумма | M21: в м2 не считаем пока | R21: X
A22: =B22&"-"&F22 -> 00- | B22: 00 | C22: =VLOOKUP(B22,ГПок!$B:$E,2,0) -> ТЭП | D22: 0 | E22: - | H22: 06 | I22: Парковка | J22: м2 | K22: проект (пока без ОС) | R22: X
A23: =B23&"-"&F23 -> 00- | B23: 00 | C23: =VLOOKUP(B23,ГПок!$B:$E,2,0) -> ТЭП | D23: 0 | E23: - | H23: 07 | I23: Кладовка | J23: м2 | R23: X
A24: =B24&"-"&F24 -> 00-06 | B24: 00 | C24: =VLOOKUP(B24,ГПок!$B:$E,2,0) -> ТЭП | D24: 0 | E24: - | F24: 06 | G24: ОБЩАЯ подземная площадь | I24: Вид ОН | J24: м2 | K24: проект (пока без ОС) | O24: X | R24: X
A25: =B25&"-"&F25 -> 00- | B25: 00 | C25: =VLOOKUP(B25,ГПок!$B:$E,2,0) -> ТЭП | D25: 0 | E25: - | H25: 01 | I25: Жилье | J25: м2 | K25: проект (пока без ОС) | R25: X
A26: =B26&"-"&F26 -> 00- | B26: 00 | C26: =VLOOKUP(B26,ГПок!$B:$E,2,0) -> ТЭП | D26: 0 | E26: - | H26: 01-01 | I26: MR Base | J26: м2 | K26: проект (пока без ОС) | R26: X
A27: =B27&"-"&F27 -> 00- | B27: 00 | C27: =VLOOKUP(B27,ГПок!$B:$E,2,0) -> ТЭП | D27: 0 | E27: - | H27: … | J27: м2 | K27: проект (пока без ОС) | R27: X
A28: =B28&"-"&F28 -> 00-07 | B28: 00 | C28: =VLOOKUP(B28,ГПок!$B:$E,2,0) -> ТЭП | D28: 0 | E28: - | F28: 07 | G28: ПОЛЕЗНАЯ наземная площадь | I28: Вид ОН | J28: м2 | K28: проект (пока без ОС) | O28: X | R28: X
A29: =B29&"-"&F29 -> 00- | B29: 00 | C29: =VLOOKUP(B29,ГПок!$B:$E,2,0) -> ТЭП | D29: 0 | E29: - | H29: 01 | I29: Жилье | J29: м2 | K29: проект (пока без ОС) | R29: X
A30: =B30&"-"&F30 -> 00- | B30: 00 | C30: =VLOOKUP(B30,ГПок!$B:$E,2,0) -> ТЭП | D30: 0 | E30: - | H30: 01-01 | I30: MR Base | J30: м2 | K30: проект (пока без ОС) | R30: X
A31: =B31&"-"&F31 -> 00- | B31: 00 | C31: =VLOOKUP(B31,ГПок!$B:$E,2,0) -> ТЭП | D31: 0 | E31: - | H31: … | J31: м2 | K31: проект (пока без ОС) | R31: X
A32: =B32&"-"&F32 -> 00-08 | B32: 00 | C32: =VLOOKUP(B32,ГПок!$B:$E,2,0) -> ТЭП | D32: 0 | E32: - | F32: 08 | G32: ПОЛЕЗНАЯ подземная площадь | I32: Вид ОН | J32: м2 | K32: проект (пока без ОС) | O32: X | R32: X
A33: =B33&"-"&F33 -> 00- | B33: 00 | C33: =VLOOKUP(B33,ГПок!$B:$E,2,0) -> ТЭП | D33: 0 | E33: - | H33: 01 | I33: Жилье | J33: м2 | K33: проект (пока без ОС) | R33: X
A34: =B34&"-"&F34 -> 00- | B34: 00 | C34: =VLOOKUP(B34,ГПок!$B:$E,2,0) -> ТЭП | D34: 0 | E34: - | H34: 01-01 | I34: MR Base | J34: м2 | K34: проект (пока без ОС) | R34: X
A35: =B35&"-"&F35 -> 00- | B35: 00 | C35: =VLOOKUP(B35,ГПок!$B:$E,2,0) -> ТЭП | D35: 0 | E35: - | H35: … | J35: м2 | K35: проект (пока без ОС) | R35: X
A36: =B36&"-"&F36 -> 00-09 | B36: 00 | C36: =VLOOKUP(B36,ГПок!$B:$E,2,0) -> ТЭП | D36: 0 | E36: - | F36: 09 | G36: Площадь лота средняя | I36: Вид ОН | J36: м2 | K36: проект (пока без ОС) | O36: X | R36: X
A37: =B37&"-"&F37 -> 00- | B37: 00 | C37: =VLOOKUP(B37,ГПок!$B:$E,2,0) -> ТЭП | D37: 0 | E37: - | H37: 01 | I37: Жилье | J37: м2 | K37: проект (пока без ОС)
A38: =B38&"-"&F38 -> 00- | B38: 00 | C38: =VLOOKUP(B38,ГПок!$B:$E,2,0) -> ТЭП | D38: 0 | E38: - | H38: 01-01 | I38: MR Base | J38: м2 | K38: проект (пока без ОС)
A39: =B39&"-"&F39 -> 00- | B39: 00 | C39: =VLOOKUP(B39,ГПок!$B:$E,2,0) -> ТЭП | D39: 0 | E39: - | H39: … | J39: м2 | K39: проект (пока без ОС)
A40: =B40&"-"&F40 -> 01-01 | B40: 01 | C40: =VLOOKUP(B40,ГПок!$B:$E,2,0) -> Продажи\контрактация | D40: 1 | E40: Операционная | F40: 01 | G40: Обьем продаж | I40: Вид ОН | J40: руб\м2 | L40: ВОПРОС как вибвать и сохранять если вначале был ПРОЕКТ а потом вдруг ПК.. Иди делать всегда нулевой ПК который распрделяется всегда? И вносим по ПК | O40: x | R40: X | S40: X
...

Sheet Справ
B3: Название | C3: Описание | D3: Тип справ | E3: Иерар | F3: Пример | G3: Доп | H3: Осн справоч
B4: Вид деятельности | C4: Группировка: опер, фин инвест | D4: закрыт | E4: нет | F4: Опер\фин\инвест | H4: -
B5: Группа показателей | C5: Группировка статей по направлениям | D5: редак | E5: нет | F5: ТЭП, Продажи | H5: -
B6: Статья | C6: Статья учета\планирования | D6: редак | E6: да | F6: Цена продажи, расходы СМР
B7: Вид ОН | C7: Вид реализуемой ОН | D7: редак | E7: да | F7: Жилье, офисы | H7: дет справ для Статьи
B8: Вид СМР ОН | D8: редак | E8: нет | F8: ЖД, ДОУ, ФОК | G8: Меппинг на Виды реализуемой - должна быть корреляция | H8: дет справ для Статьи
B9: Проекты | D9: редак | E9: нет
B10: Очереди\ПК | D10: редак | E10: да
B11: ОбСтр | D11: редак | E11: да
B12: Тип Обс | F12: ЖД, ДОУ, ФОК | G12: атрибут Обс для меппинга на Вид СМР

Sheet ВидДеят
C3: Вид деятельности CF
B4: 0 | C4: -
B5: 1 | C5: Операционная
B6: 2 | C6: Финансовая
B7: 3 | C7: Инвестиционная
B8: 9 | C8: Сроки

Sheet ВидОН
C3: Вид ОН | D3: Вид реализуемой продукции. Виды обьектов недвижимости с точки зрения их предназначения (безотносительно их расположения - могут находится внутри разных обьектов строительства)
B4: 01 | C4: Жилье
B5: 01-01 | C5: MR Base
B6: 01-02 | C6: MR Ready
B7: 01-03 | C7: без отделки
B8: 01-09 | C8: не для продажи
B9: 03 | C9: ДОУ
B10: 04 | C10: Офисы
B11: 05 | C11: Коммерческие
B12: 05-01 | C12: Ритейл
B13: 05-02 | C13: ФОК
B14: 05-03 | C14: ТЦ
B15: 05-04 | C15: Скалодром
B16: 05-05 | C16: Прочее
B17: 06 | C17: Парковка | D17: а может быть разбивка Дтлье ОФИС - в Тушино (можем забирать через привязку к типу ОбСт)
B18: 07 | C18: Кладовка

Sheet ВидСмрОН
B3: КОД | C3: Вид СМР ОН | D3: Виды обьектов производимой продукции. Классификация возводимых в рамках проекта обособленных обьектов\сооружений с точки зрения их использования\основного назначения
B4: 01 | C4: Жилье | E4: по сути виды отдельных обьектов\сооружений проекта, которые строятся\вводятся обособлено = обьектов строительства. В идеале являются сквозной аналитикой управления в графиках, планирования и учета (смета, тендер, договор, бух учет, Рнв и тп)
B5: 02 | C5: Офисы
B6: 03 | C6: ПСН
B7: 04 | C7: ДОУ
B8: 05 | C8: СОО
B9: 06 | C9: Внешний паркинг

Sheet Участки
B4: N | C4: Кадастровый номер | D4: Кадастровая стоимость | E4: Проект\ПК\УБ | F4: Город

Sheet Регион - Город
B3: шпз | C3: пп | D3: Страна | E3: пп | F3: Регион | G3: пп | H3: Город
B4: 00-00-00 | C4: 00 | D4: - | E4: 00 | F4: - | G4: 00 | H4: -
B5: 01-01-01 | C5: 01 | D5: РФ | E5: 01 | F5: Москва | G5: 01 | H5: Москва
B6: 01-02-02 | C6: 01 | D6: РФ | E6: 02 | F6: Московская область | G6: 02 | H6: Пушкино
B7: 01-02-03 | C7: 01 | D7: РФ | E7: 02 | F7: Московская область | G7: 03 | H7: Одинцово
B8: 01-03-04 | C8: 01 | D8: РФ | E8: 03 | F8: Краснодарский край | G8: 04 | H8: Краснодар
B9: 02-00-00 | C9: 02 | D9: С | E9: 00 | F9: - | G9: 00 | H9: -
B10: 03-00-00 | C10: 03 | D10: Г | E10: 00 | F10: - | G10: 00 | H10: -
B11: 04-00-00 | C11: 04 | D11: Т | E11: 00 | F11: - | G11: 00 | H11: -
B12: --
B13: --
B14: --

Sheet РАСЧЕТЫ
B2: Конструктор ЧДП - выбор какие выплаты брат ьс проекта и распрдеелять например на этот ПК при построении отчета\расчета по ЧДП)))))
B3: Если считаем плозади от ГНС, то на до забирать и вводить еще два лостфактора МР
B7: Важно где то писать и фксировать какие затраты раскидывать и не раскидывать по измерениям при налчии ГДЕТО ПОЛЬЗОВАТЕЛЬ И СИСТЕМА ДОЛЖНА ЛИБО ИКИРОСВАТЬ ПОЛЬЗОВАЕОЬ _ ЛИБО РЕШАТЬ СИСТЕМА И ЭТИ ПРАВИЛА ПРОПИСАТЬ
B10: МЕТОД ввода по месяц | C10: ОТТАСКИВАНИЕ (в прицнипе часто использвуется надо подумать может придумать механику защищенной ячейки 0 в принципе будет работать как фактическая по сути но пановая, т.к. должны из планово суммы для распред вычитаться)- Когда часть вводят в ручную а сотавшую сумму линейно размазываюь - см у МР макертинг до рнс и маркетин уже в проекте
A14: ТЭП | B14: Вопрос можно ли вводить значение на ПК и на проект одновременно - *на узел и элементы группы? (или например в наостйках выбираем проекта и все - далее меняешь но потеряешь введенные ранее узлы)

Sheet Норматив
B1: Матрица соответствия драйверов по показетелям! И ед изм
B2: в аналитике Проек-ПК-УБ если применимо
I5: вводится для каждого проекта пользователем!
A6: код | B6: пп | C6: Показатель | F6: Драйвер | H6: Формула | I6: Расценка
A7: ="p"&B7&"-"&E7 -> p05-04-05-04 | B7: 05-04 | C7: Проектирование (К+П) | D7: руб | E7: 05-04 | F7: Проектирование (К+П) | G7: руб | H7: ="00-05"+"00-04"
A8: ="p"&B8&"-"&E8 -> p05-04-05-04 | B8: 05-04 | C8: Проектирование (К+П) | D8: руб | E8: 05-04 | F8: Проектирование (К+П) | G8: руб | H8: ="00-07"+"00-08" | J8: для примера
A9: ="p"&B9&"-"&E9 -> p05-05-05-05 | B9: 05-05 | C9: Проектирование (РД) | D9: руб | E9: 05-05 | F9: Проектирование (РД) | G9: руб | H9: ="00-05"+"00-04"
A10: ="p"&B10&"-"&E10 -> p05-06-05-06 | B10: 05-06 | C10: Согласования и изыскания | D10: руб | E10: 05-06 | F10: Согласования и изыскания | G10: руб | H10: =1
A11: ="p"&B11&"-"&E11 -> p05-07-05-07 | B11: 05-07 | C11: Подготовительные СМР | D11: руб | E11: 05-07 | F11: Подготовительные СМР | G11: руб | H11: ="00-05"+"00-04"
A12: ="p"&B12&"-"&E12 -> p05-08-05-08 | B12: 05-08 | C12: СМР | D12: руб | E12: 05-08 | F12: СМР | G12: руб | H12: ="00-05"+"00-04"
A13: ="p"&B13&"-"&E13 -> p05-09-05-09 | B13: 05-09 | C13: СМР отделка | D13: руб | E13: 05-09 | F13: СМР отделка | G13: руб | H13: ="00-05"+"00-04"
A14: ="p"&B14&"-"&E14 -> p05-10-05-10 | B14: 05-10 | C14: Благоустройство общее | D14: руб | E14: 05-10 | F14: Благоустройство общее | G14: руб | H14: ="00-05"+"00-04"
A15: ="p"&B15&"-"&E15 -> p05-11-05-11 | B15: 05-11 | C15: СМР дорожной сети | D15: руб | E15: 05-11 | F15: СМР дорожной сети | G15: руб | H15: ="00-05"+"00-04"
A16: ="p"&B16&"-"&E16 -> p05-12-05-12 | B16: 05-12 | C16: СМР прочих обьектов | D16: руб | E16: 05-12 | F16: СМР прочих обьектов | G16: руб
A17: ="p"&B17&"-"&E17 -> p05-13-05-13 | B17: 05-13 | C17: Содержание площадки | D17: руб | E17: 05-13 | F17: Содержание площадки | G17: руб | H17: ="00-05"+"00-04"
A18: ="p"&B18&"-"&E18 -> p05-14-05-14 | B18: 05-14 | C18: СМР сетей и тех присоединение | D18: руб | E18: 05-14 | F18: СМР сетей и тех присоединение | G18: руб | H18: ="00-05"+"00-04"
A19: ="p"&B19&"-"&E19 -> p05-15-05-15 | B19: 05-15 | C19: Мониторинг | D19: руб | E19: 05-15 | F19: Мониторинг | G19: руб | H19: ="00-05"+"00-04"
A20: ="p"&B20&"-"&E20 -> p06-01-06-01 | B20: 06-01 | C20: Управление проектом | D20: руб | E20: 06-01 | F20: Управление проектом | G20: руб | H20: = "05-*+"06-03" | I20: 0.0375
A21: ="p"&B21&"-"&E21 -> p06-02-06-02 | B21: 06-02 | C21: Непредвиденные расходы | D21: руб | E21: 06-02 | F21: Непредвиденные расходы | G21: руб | H21: = "05-* | I21: 0.02
A22: ="p"&B22&"-"&E22 -> p06-03-06-03 | B22: 06-03 | C22: Прочие АХР | D22: руб | E22: 06-03 | F22: Прочие АХР | G22: руб
A23: ="p"&B23&"-"&E23 -> p03-01-03-01 | B23: 03-01 | C23: Реклама и маркетинг | D23: руб | E23: 03-01 | F23: Реклама и маркетинг | G23: руб | H23: расчет | I23: 0.025
A24: ="p"&B24&"-"&E24 -> p03-02-03-02 | B24: 03-02 | C24: Брокеридж | D24: руб | E24: 03-02 | F24: Брокеридж | G24: руб | H24: расчет | I24: 0.02
A25: ="p"&B25&"-"&E25 -> p03-03-03-03 | B25: 03-03 | C25: Управление продажами | D25: руб | E25: 03-03 | F25: Управление продажами | G25: руб | H25: расчет | I25: 0.012
A26: ="p"&B26&"-"&E26 -> p03-04-03-04 | B26: 03-04 | C26: Регистрация договоров | D26: руб | E26: 03-04 | F26: Регистрация договоров | G26: руб | H26: расчет??? | I26: 30000
A27: ="p"&B27&"-"&E27 -> p09-08-09-09 | B27: 09-08 | C27: Окончание продаж | D27: Дата | E27: 09-09 | F27: Дата старта продаж | G27: Дата | H27: = "09-08" - "09-09"
A28: ="p"&B28&"-"&E28 -> p00-06-p09-08-09-09 | B28: 00-06 | C28: ОБЩАЯ подземная площадь | D28: м2 | E28: p09-08-09-09 | F28: Перид продаж (p09-08-09-09) | G28: Кол-во месяцев | H28: = "00-06"/ ("09-08" - "09-09")
A29: ="p"&B29&"-"&E29 -> p01-01-01-02 | B29: 01-01 | C29: Обьем продаж | D29: м2 | E29: 01-02 | F29: Цена продаж | G29: руб/м2 | H29: = "01-01" * "01-02"
A30: ="p"&B30&"-"&E30 -> p01-03-01-03 | B30: 01-03 | C30: Кол-во продаж | D30: шт | E30: 01-03 | F30: Кол-во продаж | G30: шт | H30: расчет
A31: ="p"&B31&"-"&E31 -> p-

Sheet Ф0
C1: ТЭП
B3: Код | C3: Показатель | D3: Код | E3: Аналитика | F3: ед изм | G3: ИТОГО | H3: ИТОГО | I3: МЕС | J3: Расчет по периодам | K3: Комментарий | L3: Контроль ввода и ИИ | M3: МЕТОД ФАКТ | N3: МЕТОД ПРОГНОЗ
B4: 00-01 | C4: =VLOOKUP(B4,Показатели!$A:$M,7,0) -> Площадь ЗУ | F4: Площадь ЗУ по проекту или по ПК или обьекта | G4: Ввод | H4: ВВОД, десятичное число | I4: - | K4: Вводим условно на проект по номерам участки и далее рапсрдел по ПК и храним по ПК1
B5: 00-02 | C5: =VLOOKUP(B5,Показатели!$A:$M,7,0) -> Плотность застройки | G5: Ввод\Расчет | H5: = ВВОД = 00-04 / 00-01 | I5: - | K5: завязать их друг на друга
B6: 00-03 | C6: =VLOOKUP(B6,Показатели!$A:$M,7,0) -> ГНС ГПЗУ | G6: Ввод | I6: - | L6: = (+ -) 00-04
B7: 00-04 | C7: =VLOOKUP(B7,Показатели!$A:$M,7,0) -> ГНС наземная площадь | E7: Вид ОН | F7: Всего ГНС по проекту | G7: Расчет | H7: = Сумма по аналитике Вид ОН | I7: - | L7: = (+ -) 00-01 * 00-02,
B8: 00-0- | D8: 01 | E8: Жилье | G8: Ввод | H8: = ВВОД | I8: - | L8: = (+ -) 00-01 * 00-02,
B9: 00-0- | D9: 01-01 | E9: MR Base | G9: Ввод | H9: = ВВОД | I9: -
B10: 00-0- | D10: … | G10: Ввод | H10: = ВВОД | I10: -
B11: 00-05 | C11: =VLOOKUP(B11,Показатели!$A:$M,7,0) -> ОБЩАЯ наземная площадь | E11: Вид ОН | H11: = Сумма по аналитике Вид ОН | I11: - | L11: < 00-04
D12: 01 | E12: Жилье | H12: = ВВОД | I12: -
D13: 01-01 | E13: MR Base | H13: = ВВОД | I13: -
D14: … | H14: = ВВОД | I14: -
B15: 00-06 | C15: =VLOOKUP(B15,Показатели!$A:$M,7,0) -> ОБЩАЯ подземная площадь | E15: Вид ОН | H15: = Сумма по аналитике Вид ОН | I15: -
B16: 00-0- | D16: 01 | E16: Жилье | H16: = ВВОД | I16: -
B17: 00-0- | D17: 01-01 | E17: MR Base | H17: = ВВОД | I17: -
B18: 00-0- | D18: … | H18: = ВВОД | I18: -
B19: 00-07 | C19: =VLOOKUP(B19,Показатели!$A:$M,7,0) -> ПОЛЕЗНАЯ наземная площадь | E19: Вид ОН | H19: = Сумма по аналитике Вид ОН | I19: - | L19: < 00-05
B20: 00-0- | D20: 01 | E20: Жилье | H20: = ВВОД | I20: - | L20: < 00-05
B21: 00-0- | D21: 01-01 | E21: MR Base | H21: = ВВОД | I21: - | L21: < 00-05
B22: 00-0- | D22: … | H22: = ВВОД | I22: - | L22: < 00-05
B23: 00-08 | C23: =VLOOKUP(B23,Показатели!$A:$M,7,0) -> ПОЛЕЗНАЯ подземная площадь | E23: Вид ОН | H23: = Сумма по аналитике Вид ОН | I23: - | L23: < 00-05
B24: 00-0- | D24: 01 | E24: Жилье | H24: = ВВОД | I24: - | L24: < 00-05
B25: 00-0- | D25: 01-01 | E25: MR Base | H25: = ВВОД | I25: - | L25: < 00-05
B26: 00-0- | D26: … | H26: = ВВОД | I26: - | L26: < 00-05
B27: 71-01 | C27: =VLOOKUP(B27,Показатели!$A:$M,7,0) -> LF, % | E27: LF, % | H27: как раз увязвывет ПОЛЕЗНУЮ И ОБЩУЮ В РАЗВЕРЕВЕ ВИД ОН: - ЛИБО ВВОД - ЛИБО РАСЧЕТ см DASH | I27: -
B28: 71-02 | C28: =VLOOKUP(B28,Показатели!$A:$M,7,0) -> LF стены, % | E28: LF стены, % | H28: как раз увязвывет ПОЛЕЗНУЮ И ОБЩУЮ В РАЗВЕРЕВЕ ВИД ОН: - ЛИБО ВВОД - ЛИБО РАСЧЕТ см DASH | I28: -

Sheet Ф0БК
B1: Вводим ТЭП в разрезе Проекта- ПК-Урбан\ ОбСтр
G3: Проект | H3: 22.5
B4: ПРИМЕР | G4: ПК1 | H4: 6
G5: ПК2 | H5: 16.5
B6: шагн 1 | G6: УБ1
B7: 00-0-01 | C7: Площадь ЗУ 1 | D7: 10 | E7: 21 | F7: ПРОЕКТ
B8: 00-0-01 | C8: Площадь ЗУ 2 | D8: 12 | E8: 22 | F8: ПРОЕКТ
B10: ша2
B11: 00-0-01 | C11: Площадь ЗУ 1' | D11: 5 | E11: 21 | F11: ПК1
C12: Площадь ЗУ 1' | D12: 5 | E12: 21 | F12: ПК2
B13: 00-0-01 | C13: Площадь ЗУ 2" | D13: 6 | E13: 22 | F13: ПК1
B14: 00-0-01 | C14: Площадь ЗУ 2" | D14: 4 | E14: 22 | F14: ПК2
B17: шан 2
B18: 00-0-01 | C18: Площадь ЗУ 1' | D18: 11 | E18: 32-872793843-04953-45e | F18: Проект | G18: проект СЧИТАЕМ ДИНАМИЧЕСКИ! По ИРЕРАЗИИ ПРОЕКТ_ПК
B19: 00-0-01 | C19: Площадь ЗУ 2" | D19: 9 | E19: 32-872793843-04953-455daw | F19: Проект
B20: 00-0-01 | C20: Площадь ЗУ 1' | D20: 11 | E20: 32-872793843-04953-45e | F20: ПК1
B21: 00-0-01 | C21: Площадь ЗУ 2" | D21: 9 | E21: 32-872793843-04953-455daw | F21: ПК2

Sheet Ф1
B4: Код | C4: Показатель | D4: Код | E4: Аналитика | F4: ед изм | G4: ИТОГО | H4: МЕС | I4: Расчет по периодам | J4: Прим | K4: Комментарий | L4: Контроль ввода и ИИ | M4: МЕТОД ФАКТ | N4: МЕТОД ПРОГНОЗ
B5: 01-01 | C5: =VLOOKUP(B5,Показатели!$A:$M,7,0) -> Обьем продаж | E5: Вид ОН | G5: =Ввод = 00-07+00-08 = "00-06"/("09-08" - "09- 09") * "77-01" * "77-02" | H5: + | I5: 0. Ручной 1. Импорт извне 2. Линейно.ИТОГО указывам кол-во продаж в месяц и далее равномерно с даты старта продаж пока не будут проданы все 3. Аналитический расчет (Кулешова по параметрам) 4. Эпюра 5. Изм ИТОГО также снимаем\добавляем с конца | J5: Сред.объем продаж за период в м2 умноженный на Сезонность Коэффициент и умноженный на Тем очереди Коэффициент не превышаюший Полной Полезной площади | Y5: Пока вводим цены и все вручную а потом сделать РАСЧЕТ РАССРОЧКИ *НАПРИМЕР МЫ ВВОДИМ % ПВ И % РАССЧРОКИ и цены уже из модели кулешова (типа взвешенные) - чтобы посичтать поток Отдельно расчет расрочки и доля продаж в рассрочку, ПВ, Срок, % прироста цены для рассрочки - доп параметр - по видам ОН
B6: 01- | D6: 01 | E6: Жилье | H6: + | R6: 30 | S6: 60
B7: 01- | D7: 01-01 | E7: MR Base | H7: +
B8: 01- | D8: … | H8: + | P8: м1 | Q8: м2 | R8: м3 | S8: м4
B9: 01-02 | C9: =VLOOKUP(B9,Показатели!$A:$M,7,0) -> Цена продаж | E9: Вид ОН | G9: =Ввод | H9: + | I9: 0. Ручной 1. Дана нач цена\% дисконта и средневзве.. далее смотрим на обьем продаж (эпюру) распрделяем так чтобы вытий на нее 2. Прирост. Стартовая и проценты прирорста\лицо впррирост в рублях и колво месяц (через которые приходит прирост) плюс опции (галочки): цена не меняется с рнв с поле кол-во мес задержки, есть макс цена 3 Линейно MIN MAX. Указываем мин цену и фин цену - а по месяцам линейно считаем 4. Аналитический расчет (Кулешова по параметрам) 5. Эпюра 5. Изм ИТОГО также снимаем\добавляем с конца | P9: 20 | Q9: 5 | R9: 6 | W9: 30 | Y9: При вводе если итого больше целевого ИТОГО - уменьшать последний месяц
B10: 01- | D10: 01 | E10: Жилье | H10: + | P10: 4 | Q10: 5 | R10: 8 | S10: 13 | T10: 13 | U10: 15 | V10: 12 | W10: 11
B11: 01- | D11: 01-01 | E11: MR Base | H11: + | P11: 4 | Q11: 5 | R11: 8 | S11: 13 | T11: 13 | U11: 13 | V11: 13
B12: 01- | D12: … | H12: +
B13: 01-03 | C13: =VLOOKUP(B13,Показатели!$A:$M,7,0) -> Кол-во продаж | E13: Вид ОН | G13: =Ввод 0. Расчет через обьем\прощадь лота | H13: +
B14: 01- | D14: 01 | E14: Жилье | H14: +
B15: 01- | D15: 01-01 | E15: MR Base | H15: +
B16: 01- | D16: … | H16: +
B17: 01-04 | C17: =VLOOKUP(B17,Показатели!$A:$M,7,0) -> Продажи выручка | E17: Вид ОН | G17: =Ввод | H17: +
B18: 01- | D18: 01 | E18: Жилье | H18: +
B19: 01- | D19: 01-01 | E19: MR Base | H19: +
B20: 01- | D20: … | H20: +
B21: 02-01 | C21: =VLOOKUP(B21,Показатели!$A:$M,7,0) -> Поступления от реализации ОН | E21: Вид ОН | G21: =Ввод = Расчета - через эскроу и рассрочку!! = ОБЬЕМ НА ЦЕНУ (если нет эскроу и рассрочки-кредитных продаж) | H21: + | I21: ПОТОМ - ОПИСАТЬ БИБЛИОТЕКУ _ РАСЧЕТЫ уже черезх жскору и рассчроку - тогда подставится автоматом сюда
B22: 02- | D22: 01 | E22: Жилье | H22: +
B23: 02- | D23: 01-01 | E23: MR Base | H23: +
B24: 02- | D24: … | H24: +
B25: 02-02 | C25: =VLOOKUP(B25,Показатели!$A:$M,7,0) -> Прочие опер поступления | G25: =Ввод | H25: +
B26: 02-03 | C26: =VLOOKUP(B26,Показатели!$A:$M,7,0) -> Поступления по аренде | G26: =Ввод | H26: +
B27: 02-04 | C27: =VLOOKUP(B27,Показатели!$A:$M,7,0) -> Поступления по услугам эксплуатации | G27: =Ввод | H27: +
B28: 02-05 | C28: =VLOOKUP(B28,Показатели!$A:$M,7,0) -> Реализация основных средств | F28: руб | G28: =Ввод | H28: +
B29: 02-06 | C29: =VLOOKUP(B29,Показатели!$A:$M,7,0) -> Прочие поступления ЗУ+ | F29: руб | G29: =Ввод | H29: +
B30: 02-07 | C30: =VLOOKUP(B30,Показатели!$A:$M,7,0) -> Прочие поступления % | F30: руб | G30: =Ввод | H30: +
I34: ВСЕМ ОСТАЛЬНЫМ ФИНАНСГВЫМ ПЫТАЕМСЯ СДЕЛАТЬ НОКПКУЦ С ДОП ВВОДОМ _ ТИПА КПАЬЛЯЛТОР _ ВВЕДИ РАСЦЕНКУ И ВЫВОДИМ ДРАЙЫЕР ИЛИ СРАЗУ ВВЕДИ ИТОГО ПО ПРОЕКТИРОВАНИЮ НАПРИМЕР.

Sheet Ф1БК _Л
A1: 1 пример как описываем калькуляции - каждый расчет
B3: Данные для расчетов:
B5: Лист | C5: код | D5: Название | E5: Название_1 | F5: Ввод данных | G5: ед.измерения | H5: Расчет | I5: Описательная часть расчета
B6: Ф0!B26 | C6: 00-07 | D6: Контрактация | E6: =Ф0!C19 -> ПОЛЕЗНАЯ наземная площадь | F6: Автоматически | G6: м2
C7: =Показатели!A119 -> 77-01 | D7: Контрактация | E7: Сезонность Коэффициент | F7: каждый период | G7: % | H7: ручной ввод | I7: Вводится на каждый период
C8: =Показатели!A120 -> 77-02 | D8: Контрактация | E8: Темп очереди Коэффициент | F8: каждый период | G8: % | H8: ручной ввод | I8: Вводится на каждый период
D9: Контрактация | E9: Кол-во периодов | G9: число | H9: =ручной ввод = "09-08" - "09- 09" (кол-во месяцев) | I9: Вводится на каждый период или расчетным способом
E10: Средний объем продаж | G10: м2 | H10: = ручной = "00-06"/("09-08" - "09- 09") | I10: Вводится один раз или же расчитывается автоматически
C11: 01-01 | D11: Обьем продаж | E11: =D11 -> Обьем продаж | F11: Расчетный | G11: м2 | H11: = ЕСЛИ(СУММ(( ( "00-07"/ "Д3") * "Д1") * "Д2" по прошлым периода; ( ("00-07" / "Д3") * "Д1") * "Д2" - текущий период )<= "00-07" ; ( ("00-07" / "Д3") * "Д1") * "Д2" - текущий период ;ЕСЛИ(СУММ( ( ("00-07" / "Д3") * "Д1") * "Д2" - прошлых периодов;( ("00-07" / "Д3") * "Д1") * "Д2" - текущий период )- "00-07" >=0; "00-07" -СУММ(( "00-07" / "Д3") * "Д1") * "Д2" - прошлых периодов);0)) | I11: Сред.объем продаж за период в м2 умноженный на Сезонность Коэффициент и умноженный на Тем очереди Коэффициент не превышаюший Полной Полезной площади
A13: Вводные данные
B14: 00-0-02 | C14: Итого офисов, м2
B15: 00-010- | C15: Дата страта продаж по данному ПК
B19: ВВОД | C19: Кол-во м2 в месяц
A22: ИТОГО | B22: 01-0-02 | C22: в разерез ПК в месяц = итого метров поделить пока кол-во м2 не закончится
B25: Пример расчета:
E26: Сред | F26: В квартал | G26: В квартал | H26: В квартал | I26: В квартал | J26: В квартал | K26: В квартал | L26: В квартал | M26: В квартал | N26: В квартал | O26: В квартал | P26: В квартал
B27: Контрактация | E27: =D28/D29 -> 2654.5 | G27: =G31 -> 2123.6 | H27: 2150.145 | I27: 2389.05 | J27: 2389.05 | K27: 2389.05 | L27: 10618 | M27: 10618 | N27: 10618 | O27: 9795.105 | P27: 0
B28: ТЭП | C28: Полезная площадь | D28: 53090
B29: руч.ввод | C29: Делят на число | D29: 20 | E29: Среднее чего?
B30: руч.ввод | C30: Сезонность | D30: 1 | E30: каждый кв | G30: =$E$27*G33 -> 2654.5 | H30: =$E$27*H33 -> 2389.05 | I30: =$E$27*I33 -> 2654.5 | J30: =$E$27*J33 -> 2654.5 | K30: =$E$27*K33 -> 2654.5 | L30: =$E$27*L33 -> 2654.5 | M30: =$E$27*M33 -> 2654.5 | N30: =$E$27*N33 -> 2654.5 | ... P30: =$E$27*P33 -> 2654.5
B31: руч.ввод | C31: Темп очереди | D31: 0.8 | E31: каждый кв | G31: =G30*G34 -> 2123.6 | H31: =H30*H34 -> 2150.145 | I31: =I30*I34 -> 2389.05 | J31: =J30*J34 -> 2389.05 | K31: =K30*K34 -> 2389.05 | L31: =L30*L34 -> 10618 | M31: =M30*M34 -> 10618 | N31: =N30*N34 -> 10618 | ... P31: =P30*P34 -> 10618
B33: руч.ввод | C33: Сезонность | G33: 1 | H33: 0.9 | I33: 1 | J33: 1 | K33: 1 | L33: 1 | M33: 1 | N33: 1 | O33: 1 | P33: 1
B34: руч.ввод | C34: Темп очереди | G34: 0.8 | H34: 0.9 | I34: 0.9 | J34: 0.9 | K34: 0.9 | L34: 4 | M34: 4 | N34: 4 | O34: 4 | P34: 4
A41: 2 пример почему вводить важно доля расрочки имеено в обьеме!!! И подееи описать как считается показатель тут ПОСТУПЛЕНИЯ (его нельзя вводить (делаем только расчетным
A42: Доля рассрочки в обьеме продажи и в поступления разные вещи - сейчас они вводят в постулпении его, а формально надо рассчитывать от % в обьеме через расчет кулешова.
A43: Пока решили что в CF вводим долю рассчроки в ОБЬЕМЕ а не поступления (хотя показатель вразделе поступления)
B45: Лист | C45: код | D45: Название | E45: Название_1 | F45: Ввод данных | G45: ед.измерения | H45: Расчет | I45: Описательная часть расчета
C46: =Показатели!A121 -> 77-03 | D46: Цена продаж | E46: Старт продаж (цена на начало) | F46: единожды | G46: руб | H46: ручной ввод | I46: вводится один раз
C47: Д6 | D47: Цена продаж | E47: Наценка на рассрочку | F47: каждый период | G47: % | H47: ручной ввод | I47: Либо возможность выбора на весь период какой-то процент
C48: Д7 | D48: Цена продаж | E48: Индексация | F48: каждый период | G48: % | H48: ручной ввод | I48: Либо возможность выбора на весь период какой-то процент
D49: Дата начала | E49: Автоматически | F49: дата | G49: ГРП | H49: автоматически
C50: 01-02 | D50: Цена продаж | H50: Если ( "01-01" больше 0 и цена за м2 за прошлый период равно 0, тогда "Сарт продаж" умноженная на Наценку на рассрочку тек.периода, в противном случае цена за м2 кв за прошлый период деленная на 1- Наценка на рассрочка прошлого периода умноженная на 1+Наценку на рассрочку тек периода умноженная на 1+Индексация тек.периода
B52: Пример расчета:
B54: Цена за м2 с учетом рассрочки | G54: 577.5 | H54: 583.275 | I54: 583.6083 | J54: 601.11655 | K54: 619.15005 | L54: 637.72455 | M54: 656.85628 | N54: 663.29605 | O54: 683.19493 | P54: 0
B55: руч.ввод | C55: Старт продаж | D55: 550
C56: Рассрочка
B57: руч.ввод | C57: Доля рассрочки | D57: 0.3 | G57: 0.3 | H57: 0.3 | I57: 0.2 | J57: 0.2 | K57: 0.2 | L57: 0.2 | M57: 0.2
B58: руч.ввод | C58: Наценка на рассрочку | D58: 0.05 | G58: =D58 -> 0.05 | H58: 0.05 | I58: 0.02 | J58: 0.02 | K58: 0.02 | L58: 0.02 | M58: 0.02
B60: руч.ввод | C60: Индексация | D60: 1-3% | E60: ??? | G60: 0 | H60: 0.01 | I60: 0.03 | J60: 0.03 | K60: 0.03 | L60: 0.03 | M60: 0.03 | N60: 0.03 | O60: 0.03 | P60: 0.03
A64: в расчетах обьема продаж и цены - судя по всему нет все таки лимита на емкость олкации( тупо размазывают на 4 года обьем:)))
...

Sheet Ф1БК
A1: 1 пример как описываем калькуляции - каждый расчет
B2: 01-01 | C2: Обьем продаж
B3: 2. | C3: Линейно | E3: МНОГО СЛОВО ПО АЛГОРИТМЫ _ ЧТОБЫ ПОНЯТ ЬСУТЬ И ЦЕЛЬ
A5: Взодные данные
B6: 00-0-02 | C6: Итого офисов, м2
B7: 00-010- | C7: Дата страта прлдаж по данному ПК
B9: ВВОД | C9: Кол-во м2 в месяц
A12: ИТОГО | B12: 01-0-02 | C12: в разерез ПК в месяц = итого метров поделить пока колзво м2 не закончится
C17: 5000 | E17: май 20255 | F17: 45809
C18: 45748 | E18: 30 | F18: 30 | G18: 30 | H18: .. | I18: .. | J18: . | K18: 12
C19: 30
A31: 2 пример почему вводить важно долб расрочки вимеено в оьеме!!! И по дееи описат ькак счиаттьется показатель тут ПОСТУПЛЕНИЯ (его нельзя вводить (делаем только расчетным
A32: Долря расчроки в обьеме продажа и в поступления разные вещи - сейчас они вводят в постулпении его, а формально надо рассчитывать от % в обьеме через расчет кулешова.
A33: Пока решили чтов CF вводим долю рассчроки в ОБЬЕМЕ а не поступления (хотя показатель вразделе поступления)
C35: м2 | E35: цена | G35: контакрация | K35: ПОСТУПЛЕНИЯ | L35: % ДОЛЯ РАССЧРОКИ
A36: обьем продаж | C36: 60 | G36: =СУММ(G37:G38) -> #NAME?
B37: прямые | C37: 20 | E37: 100 | G37: 2000
B38: расрчоки | C38: 40 | E38: 110 | G38: 4400
C40: % обьеме | G40: % продаж | L40: 8.08
C41: 66 | G41: =G38/G36 -> #NAME?
C42: вводим его
A47: в расчетах обьема продаж и цены - судя по всему нет все таки лимита на емкость олкации( тупо размазывают на 4 года обьем:)))

Sheet Ф3
B4: Код | C4: Показатель | D4: Код | E4: Аналитика | F4: ед изм | G4: ИТОГО | H4: МЕС | I4: Расчет по периодам | J4: Комментарий | K4: Контроль ввода и ИИ | L4: МЕТОД ФАКТ | M4: МЕТОД ПРОГНОЗ
B5: 03-01 | C5: Реклама и маркетинг | G5: = ВВОД = p03-01-01-04 | I5: 0. Ручной ввод 1. Фикс в месяц продажи<>0. ЗНАЧ = ИТОГО / кол-во месяцев в которых продажи были не нулевые. Если продажи ноль в месяце то и ЗНАЧ =0. Плюс можно указать сдвиг - например= -2 месяца (расходы маркетинга опережают продажи) 2. Линейно Продажам. ЗНАЧ = ИТОГО ПРОДАЖИ\ИТОГО Маркетинг * Продажи месяца. Плюс можно указать сдвиг - например= -2 месяца (расходы маркетинга опережают продажи) 3. Фикс в месяц за период . ЗНАЧ = ИТОГО/(МАКС месяц продажи - МИН месяц Продажи). Плюс можно указать сдвиг - например= -2 месяца (расходы маркетинга опережают продажи) 4. Линейно РнС-РнВ. Сумма поступления по продажам * (умножить) на % (Маркетинг и реклама) и вся сумма делится на количество периодов (РнВ-РнС) 4. Эпюра 5. Изм ИТОГО также снимаем\добавляем с конца | J5: 1 - ДЕТАЛИЗАЦИЮ БЕРЕМ ПО СТАТЬЯМ ИЛИ 4 СТАТЬИ ТОЛЬКО ПЛАНИРУЕМ КАК db Сейчас идет детализация и часть расходов оттаскивается и вводится вручную - например маркетинг до РНС 2 - КОММ - в ФМ сначала сылаются на поступления - при расчете ИТОГО, а когда по месяцам то маркетинг не ноль если контрактация не ноль в этом месяц- в общем случае может расходится (надо ссылться везде на контакратцию). ТК контакратация у МР совпадает с Поступлениями итого (не считают выручку Брутто а сразу Нетто, то лучше использовать Контакратаци=продажи везде) 3. КАК ПОСТУПАЕМ ПО МЕТОДИКЕ ЕСЛИ БЫЛ ФАКТ РАСХОДОВ НАПРИМЕР по 1,5% первые 2 месяца, а на оставшиеся месяца счиатем все также по нормативу или пытаемся нагнать и выйти на итоговый на 2,5% от всего
B6: 03-02 | C6: Брокеридж | G6: = ВВОД = p03-02-01-04 | I6: 0. Ручной ввод 1. ЗНАЧ тек месяца/периода = (Поступления или Контрактация прошлого месяца/периода) * %. ДДС ссдвиг на +1 месяц/период Можно указывать сдвиг 4. Эпюра 5. Изм ИТОГО также снимаем\добавляем с конца | J6: Для себя: При подтягивании факта Контрактации/Поступлений будет автоматически пересчитываться показатель
B7: 03-03 | C7: Управление продажами | G7: = ВВОД = p03-03-01-04 | I7: 0. Ручной ввод 1. ЗНАЧ тек месяца/периода = (Поступления или Контрактация прошлого месяца/периода) * %. ДДС сдвиг на +1 месяц/период Можно указывать сдвиг 4. Эпюра 5. Изм ИТОГО также снимаем\добавляем с конца | J7: Для себя: При подтягивании факта Контрактации/Поступлений будет автоматически пересчитываться показатель
B8: 03-04 | C8: Регистрация договоров | G8: = ВВОД = p03-04-01-03 | I8: 0. Ручной ввод 1. ЗНАЧ = Сумма тек месяца( (Контрактация м2 / S лота ) по каждому ОН + кол-во Парковочных мест ) * стоимость регистрации договора + если первый месяц РнВ то( (Сумма остатка Контрактация м2 / S лота) по каждому ОН + Сумма кол-ва остатка Парковочных мест ) * стоимость регистрации договора 4. Эпюра 5. Изм ИТОГО также снимаем\добавляем с конца | J8: Для себя: При подтягивании факта Контрактации/Поступлений будет автоматически пересчитываться показатель

Sheet Ф3БК 03
A1: 1 Расчет на Рекламу и маркетинг
B2: =Ф3!B5 | C2: =Ф3!C5 -> Реклама и маркетинг
C3: Название
B4: 1. | C4: Фикс в месяц продажи<>0.
C5: Описание
C6: Расходы на Рекламу и маркетинг расчитываются исходя из суммы продаж и линейно распределяются по периодам пока не закончится график продаж
